Workbook

Sheet Read Me
A1: StructuralGuard Blind Test Workbook
A3: Scenario | B3: Student grade review
A4: Random seed | B4: 44077
A5: Generated rows | B5: 180
A6: Purpose | B6: Blind structural-formula anomaly evaluation
A7: Answer location | B7: Stored outside this workbook
A8: Safety | B8: Do not overwrite this source workbook during analysis

Sheet Config
A1: Assumptions
A2: Parameter | B2: Value
A3: Pass mark | B3: 60
A4: Maximum mark | B4: 100

Sheet Grades
A1: Student Grade Review
A2: Student ID | B2: Math | C2: English | D2: Science | E2: History | F2: Computing | G2: Average | H2: Status | I2: Highest | J2: Lowest | K2: Spread
A3: STU-0001 | B3: 87 | C3: 54 | D3: 81 | E3: 81 | F3: 78 | G3: =ROUND(AVERAGE(B3:F3),1) | H3: =IF(MIN(B3:F3)>='Config'!$B$3,"PASS","REVIEW") | I3: =MAX(B3:F3) | J3: =MIN(B3:F3) | K3: =I3-J3
A4: STU-0002 | B4: 35 | C4: 80 | D4: 89 | E4: 81 | F4: 59 | G4: =ROUND(AVERAGE(B4:F4),1) | H4: =IF(MIN(B4:F4)>='Config'!$B$3,"PASS","REVIEW") | I4: =MAX(B4:F4) | J4: =MIN(B4:F4) | K4: =I4-J4
A5: STU-0003 | B5: 67 | C5: 71 | D5: 78 | E5: 71 | F5: 49 | G5: =ROUND(AVERAGE(B5:F5),1) | H5: =IF(MIN(B5:F5)>='Config'!$B$3,"PASS","REVIEW") | I5: =MAX(B5:F5) | J5: =MIN(B5:F5) | K5: =I5-J5
A6: STU-0004 | B6: 71 | C6: 73 | D6: 64 | E6: 55 | F6: 67 | G6: =ROUND(AVERAGE(B6:F6),1) | H6: =IF(MIN(B6:F6)>='Config'!$B$3,"PASS","REVIEW") | I6: =MAX(B6:F6) | J6: =MIN(B6:F6) | K6: =I6-J6
A7: STU-0005 | B7: 85 | C7: 79 | D7: 84 | E7: 36 | F7: 96 | G7: =ROUND(AVERAGE(B7:F7),1) | H7: =IF(MIN(B7:F7)>='Config'!$B$3,"PASS","REVIEW") | I7: =MAX(B7:F7) | J7: =MIN(B7:F7) | K7: =I7-J7
A8: STU-0006 | B8: 94 | C8: 45 | D8: 64 | E8: 92 | F8: 84 | G8: =ROUND(AVERAGE(B8:F8),1) | H8: =IF(MIN(B8:F8)>='Config'!$B$3,"PASS","REVIEW") | I8: =MAX(B8:F8) | J8: =MIN(B8:F8) | K8: =I8-J8
A9: STU-0007 | B9: 96 | C9: 40 | D9: 64 | E9: 57 | F9: 46 | G9: =ROUND(AVERAGE(B9:F9),1) | H9: =IF(MIN(B9:F9)>='Config'!$B$3,"PASS","REVIEW") | I9: =MAX(B9:F9) | J9: =MIN(B9:F9) | K9: =I9-J9
A10: STU-0008 | B10: 94 | C10: 70 | D10: 60 | E10: 96 | F10: 75 | G10: =ROUND(AVERAGE(B10:F10),1) | H10: =IF(MIN(B10:F10)>='Config'!$B$3,"PASS","REVIEW") | I10: =MAX(B10:F10) | J10: =MIN(B10:F10) | K10: =I10-J10
A11: STU-0009 | B11: 51 | C11: 94 | D11: 67 | E11: 88 | F11: 49 | G11: =ROUND(AVERAGE(B11:F11),1) | H11: =IF(MIN(B11:F11)>='Config'!$B$3,"PASS","REVIEW") | I11: =MAX(B11:F11) | J11: =MIN(B11:F11) | K11: =I11-J11
A12: STU-0010 | B12: 55 | C12: 44 | D12: 78 | E12: 49 | F12: 45 | G12: =ROUND(AVERAGE(B12:F12),1) | H12: =IF(MIN(B12:F12)>='Config'!$B$3,"PASS","REVIEW") | I12: =MAX(B12:F12) | J12: =MIN(B12:F12) | K12: =I12-J12
A13: STU-0011 | B13: 36 | C13: 53 | D13: 70 | E13: 95 | F13: 47 | G13: =ROUND(AVERAGE(B13:F13),1) | H13: =IF(MIN(B13:F13)>='Config'!$B$3,"PASS","REVIEW") | I13: =MAX(B13:F13) | J13: =MIN(B13:F13) | K13: =I13-J13
A14: STU-0012 | B14: 71 | C14: 58 | D14: 35 | E14: 51 | F14: 86 | G14: =ROUND(AVERAGE(B14:F14),1) | H14: =IF(MIN(B14:F14)>='Config'!$B$3,"PASS","REVIEW") | I14: =MAX(B14:F14) | J14: =MIN(B14:F14) | K14: =I14-J14
A15: STU-0013 | B15: 84 | C15: 72 | D15: 39 | E15: 75 | F15: 66 | G15: =ROUND(AVERAGE(B15:F15),1) | H15: =IF(MIN(B15:F15)>='Config'!$B$3,"PASS","REVIEW") | I15: =MAX(B15:F15) | J15: =MIN(B15:F15) | K15: =I15-J15
A16: STU-0014 | B16: 97 | C16: 100 | D16: 44 | E16: 90 | F16: 38 | G16: =ROUND(AVERAGE(B16:E16),1) | H16: =IF(MIN(B16:F16)>='Config'!$B$3,"PASS","REVIEW") | I16: =MAX(B16:F16) | J16: =MIN(B16:F16) | K16: =I16-J16
A17: STU-0015 | B17: 100 | C17: 97 | D17: 75 | E17: 85 | F17: 72 | G17: =ROUND(AVERAGE(B17:E17),1) | H17: =IF(MIN(B17:F17)>='Config'!$B$3,"PASS","REVIEW") | I17: =MAX(B17:F17) | J17: =MIN(B17:F17) | K17: =I17-J17
A18: STU-0016 | B18: 65 | C18: 74 | D18: 93 | E18: 66 | F18: 76 | G18: =ROUND(AVERAGE(B18:E18),1) | H18: =IF(MIN(B18:F18)>='Config'!$B$3,"PASS","REVIEW") | I18: =MAX(B18:F18) | J18: =MIN(B18:F18) | K18: =I18-J18
A19: STU-0017 | B19: 50 | C19: 81 | D19: 63 | E19: 99 | F19: 58 | G19: =ROUND(AVERAGE(B19:E19),1) | H19: =IF(MIN(B19:F19)>='Config'!$B$3,"PASS","REVIEW") | I19: =MAX(B19:F19) | J19: =MIN(B19:F19) | K19: =I19-J19
A20: STU-0018 | B20: 67 | C20: 57 | D20: 89 | E20: 70 | F20: 67 | G20: =ROUND(AVERAGE(B20:E20),1) | H20: =IF(MIN(B20:F20)>='Config'!$B$3,"PASS","REVIEW") | I20: =MAX(B20:F20) | J20: =MIN(B20:F20) | K20: =I20-J20
A21: STU-0019 | B21: 39 | C21: 40 | D21: 40 | E21: 73 | F21: 97 | G21: =ROUND(AVERAGE(B21:E21),1) | H21: =IF(MIN(B21:F21)>='Config'!$B$3,"PASS","REVIEW") | I21: =MAX(B21:F21) | J21: =MIN(B21:F21) | K21: =I21-J21
A22: STU-0020 | B22: 54 | C22: 100 | D22: 63 | E22: 40 | F22: 74 | G22: =ROUND(AVERAGE(B22:E22),1) | H22: =IF(MIN(B22:F22)>='Config'!$B$3,"PASS","REVIEW") | I22: =MAX(B22:F22) | J22: =MIN(B22:F22) | K22: =I22-J22
A23: STU-0021 | B23: 78 | C23: 79 | D23: 39 | E23: 90 | F23: 41 | G23: =ROUND(AVERAGE(B23:E23),1) | H23: =IF(MIN(B23:F23)>='Config'!$B$3,"PASS","REVIEW") | I23: =MAX(B23:F23) | J23: =MIN(B23:F23) | K23: =I23-J23
A24: STU-0022 | B24: 74 | C24: 61 | D24: 89 | E24: 41 | F24: 65 | G24: =ROUND(AVERAGE(B24:E24),1) | H24: =IF(MIN(B24:F24)>='Config'!$B$3,"PASS","REVIEW") | I24: =MAX(B24:F24) | J24: =MIN(B24:F24) | K24: =I24-J24
A25: STU-0023 | B25: 63 | C25: 69 | D25: 63 | E25: 80 | F25: 76 | G25: =ROUND(AVERAGE(B25:E25),1) | H25: =IF(MIN(B25:F25)>='Config'!$B$3,"PASS","REVIEW") | I25: =MAX(B25:F25) | J25: =MIN(B25:F25) | K25: =I25-J25
A26: STU-0024 | B26: 42 | C26: 93 | D26: 61 | E26: 90 | F26: 78 | G26: =ROUND(AVERAGE(B26:E26),1) | H26: =IF(MIN(B26:F26)>='Config'!$B$3,"PASS","REVIEW") | I26: =MAX(B26:F26) | J26: =MIN(B26:F26) | K26: =I26-J26
A27: STU-0025 | B27: 90 | C27: 81 | D27: 87 | E27: 40 | F27: 61 | G27: =ROUND(AVERAGE(B27:E27),1) | H27: =IF(MIN(B27:F27)>='Config'!$B$3,"PASS","REVIEW") | I27: =MAX(B27:F27) | J27: =MIN(B27:F27) | K27: =I27-J27
... A35: STU-0033 | B35: 48 | C35: 94 | D35: 72 | E35: 54 | F35: 97 | G35: =ROUND(AVERAGE(B35:E35),1) | H35: =IF(MIN(B35:F35)>='Config'!$B$3,"PASS","REVIEW") | I35: =MAX(B35:F35) | J35: =MIN(B35:F35) | K35: =I35-J35
A36: STU-0034 | B36: 98 | C36: 72 | D36: 85 | E36: 84 | F36: 58 | G36: =ROUND(AVERAGE(B36:F36),1) | H36: =IF(MIN(B36:F36)>='Config'!$B$3,"PASS","REVIEW") | I36: =MAX(B36:F36) | J36: =MIN(B36:F36) | K36: =I36-J36
A37: STU-0035 | B37: 86 | C37: 53 | D37: 53 | E37: 37 | F37: 72 | G37: =ROUND(AVERAGE(B37:F37),1) | H37: =IF(MIN(B37:F37)>='Config'!$B$3,"PASS","REVIEW") | I37: =MAX(B37:F37) | J37: =MIN(B37:F37) | K37: =I37-J37
A38: STU-0036 | B38: 46 | C38: 76 | D38: 35 | E38: 84 | F38: 72 | G38: =ROUND(AVERAGE(B38:F38),1) | H38: =IF(MIN(B38:F38)>='Config'!$B$3,"PASS","REVIEW") | I38: =MAX(B38:F38) | J38: =MIN(B38:F38) | K38: =I38-J38
A39: STU-0037 | B39: 43 | C39: 35 | D39: 51 | E39: 83 | F39: 82 | G39: =ROUND(AVERAGE(B39:F39),1) | H39: =IF(MIN(B39:F39)>='Config'!$B$3,"PASS","REVIEW") | I39: =MAX(B39:F39) | J39: =MIN(B39:F39) | K39: =I39-J39
A40: STU-0038 | B40: 40 | C40: 51 | D40: 50 | E40: 98 | F40: 53 | G40: =ROUND(AVERAGE(B40:F40),1) | H40: =IF(MIN(B40:F40)>='Config'!$B$3,"PASS","REVIEW") | I40: =MAX(B40:F40) | J40: =MIN(B40:F40) | K40: =I40-J40
A41: STU-0039 | B41: 51 | C41: 40 | D41: 75 | E41: 38 | F41: 92 | G41: =ROUND(AVERAGE(B41:F41),1) | H41: =IF(MIN(B41:F41)>='Config'!$B$3,"PASS","REVIEW") | I41: =MAX(B41:F41) | J41: =MIN(B41:F41) | K41: =I41-J41
A42: STU-0040 | B42: 74 | C42: 38 | D42: 66 | E42: 52 | F42: 96 | G42: =ROUND(AVERAGE(B42:F42),1) | H42: =IF(MIN(B42:F42)>='Config'!$B$3,"PASS","REVIEW") | I42: =MAX(B42:F42) | J42: =MIN(B42:F42) | K42: =I42-J42
A43: STU-0041 | B43: 57 | C43: 72 | D43: 42 | E43: 43 | F43: 55 | G43: =ROUND(AVERAGE(B43:F43),1) | H43: =IF(MIN(B43:F43)>='Config'!$B$3,"PASS","REVIEW") | I43: =MAX(B43:F43) | J43: =MIN(B43:F43) | K43: =I43-J43
A44: STU-0042 | B44: 88 | C44: 66 | D44: 88 | E44: 46 | F44: 88 | G44: =ROUND(AVERAGE(B44:F44),1) | H44: =IF(MIN(B44:F44)>='Config'!$B$3,"PASS","REVIEW") | I44: =MAX(B44:F44) | J44: =MIN(B44:F44) | K44: =I44-J44
A45: STU-0043 | B45: 85 | C45: 92 | D45: 85 | E45: 85 | F45: 66 | G45: =ROUND(AVERAGE(B45:F45),1) | H45: =IF(MIN(B45:F45)>='Config'!$B$3,"PASS","REVIEW") | I45: =MAX(B45:F45) | J45: =MIN(B45:F45) | K45: =I45-J45
A46: STU-0044 | B46: 75 | C46: 79 | D46: 99 | E46: 68 | F46: 40 | G46: =ROUND(AVERAGE(B46:F46),1) | H46: =IF(MIN(B46:F46)>='Config'!$B$3,"PASS","REVIEW") | I46: =MAX(B46:F46) | J46: =MIN(B46:F46) | K46: =I46-J46
A47: STU-0045 | B47: 77 | C47: 36 | D47: 51 | E47: 96 | F47: 76 | G47: =ROUND(AVERAGE(B47:F47),1) | H47: =IF(MIN(B47:F47)>='Config'!$B$3,"PASS","REVIEW") | I47: =MAX(B47:F47) | J47: =MIN(B47:F47) | K47: =I47-J47
...
