Workbook

Sheet Read Me
A1: StructuralGuard Blind Test Workbook
A3: Scenario | B3: Project budget portfolio
A4: Random seed | B4: 33061
A5: Generated rows | B5: 160
A6: Purpose | B6: Blind structural-formula anomaly evaluation
A7: Answer location | B7: Stored outside this workbook
A8: Safety | B8: Do not overwrite this source workbook during analysis

Sheet Rates
A1: Assumptions
A2: Parameter | B2: Value
A3: Contingency rate | B3: 0.08
A4: Overhead rate | B4: 0.12

Sheet Projects
A1: Project Budget Portfolio
A2: Project | B2: Department | C2: Labor | D2: Materials | E2: Travel | F2: Subtotal | G2: Contingency | H2: Overhead | I2: Approved Budget | J2: Total Cost | K2: Variance
A3: PRJ-001 | B3: Technology | C3: 64785.84 | D3: 22618.96 | E3: 5173.16 | F3: =SUM(C3:E3) | G3: =F3*'Rates'!$B$3 | H3: =F3*'Rates'!$B$4 | I3: 115981 | J3: =SUM(F3:H3) | K3: =I3-J3
A4: PRJ-002 | B4: Operations | C4: 34622.39 | D4: 2509.05 | E4: 6601.06 | F4: =SUM(C4:E4) | G4: =F4*'Rates'!$B$3 | H4: =F4*'Rates'!$B$4 | I4: 52369 | J4: =SUM(F4:H4) | K4: =I4-J4
A5: PRJ-003 | B5: Marketing | C5: 62560.28 | D5: 13617.03 | E5: 9587.97 | F5: =SUM(C5:E5) | G5: =F5*'Rates'!$B$3 | H5: =F5*'Rates'!$B$4 | I5: 103569 | J5: =SUM(F5:H5) | K5: =I5-J5
A6: PRJ-004 | B6: Marketing | C6: 40775.21 | D6: 18304.46 | E6: 1930.39 | F6: =SUM(C6:E6) | G6: =F6*'Rates'!$B$3 | H6: =F6*'Rates'!$B$4 | I6: 74700 | J6: =SUM(F6:H6) | K6: =I6-J6
A7: PRJ-005 | B7: Operations | C7: 48724.02 | D7: 37312.53 | E7: 7476.34 | F7: =SUM(C7:E7) | G7: =F7*'Rates'!$B$3 | H7: =F7*'Rates'!$B$4 | I7: 119361 | J7: =SUM(F7:H7) | K7: =I7-J7
A8: PRJ-006 | B8: Marketing | C8: 68593.88 | D8: 16718.73 | E8: 1277.41 | F8: =SUM(C8:E8) | G8: =F8*'Rates'!$B$3 | H8: =F8*'Rates'!$B$4 | I8: 105237 | J8: =SUM(F8:H8) | K8: =I8-J8
A9: PRJ-007 | B9: Operations | C9: 47014.53 | D9: 18150.28 | E9: 3913.85 | F9: =SUM(C9:E9) | G9: =F9*'Rates'!$B$3 | H9: =F9*'Rates'!$B$4 | I9: 86838 | J9: =SUM(F9:H9) | K9: =I9-J9
A10: PRJ-008 | B10: Technology | C10: 27074.39 | D10: 4237.25 | E10: 7923.1 | F10: =SUM(C10:E10) | G10: =F10*'Rates'!$B$3 | H10: =F10*'Rates'!$B$4 | I10: 50196 | J10: =SUM(F10:H10) | K10: =I10-J10
A11: PRJ-009 | B11: Technology | C11: 54308.67 | D11: 33520.46 | E11: 2886.85 | F11: =SUM(C11:E11) | G11: =F11*'Rates'!$B$3 | H11: =F11*'Rates'!$B$4 | I11: 117814 | J11: =SUM(F11:H11) | K11: =I11-J11
A12: PRJ-010 | B12: Research | C12: 49522.12 | D12: 36822.24 | E12: 4233.36 | F12: =SUM(C12:E12) | G12: =F12*'Rates'!$B$3 | H12: =F12*'Rates'!$B$4 | I12: 111016 | J12: =SUM(F12:H12) | K12: =I12-J12
A13: PRJ-011 | B13: Research | C13: 56023.16 | D13: 5716.5 | E13: 1532.93 | F13: =SUM(C13:E13) | G13: =F13*'Rates'!$B$3 | H13: =F13*'Rates'!$B$4 | I13: 82238 | J13: =SUM(F13:H13) | K13: =I13-J13
A14: PRJ-012 | B14: Research | C14: 17605.96 | D14: 2437.88 | E14: 3748.01 | F14: =SUM(C14:E14) | G14: =F14*'Rates'!$B$3 | H14: =F14*'Rates'!$B$4 | I14: 28106 | J14: =SUM(F14:H14) | K14: =I14-J14
... A33: PRJ-031 | B33: Operations | C33: 63809.65 | D33: 2731.01 | E33: 1265.48 | F33: =SUM(C33:E33) | G33: =F33*'Rates'!$B$3 | H33: =F33*'Rates'!$B$4 | I33: 80317 | J33: =SUM(F33:H33) | K33: =I33-J33
A34: PRJ-032 | B34: Operations | C34: 5594.34 | D34: 14942.73 | E34: 3034.82 | F34: =SUM(C34:D34) | G34: =F34*'Rates'!$B$3 | H34: =F34*'Rates'!$B$4 | I34: 29816 | J34: =SUM(F34:H34) | K34: =I34-J34
A35: PRJ-033 | B35: Operations | C35: 38800.83 | D35: 23928.3 | E35: 7907.38 | F35: =SUM(C35:E35) | G35: =F35*'Rates'!$B$3 | H35: =F35*'Rates'!$B$4 | I35: 89790 | J35: =SUM(F35:H35) | K35: =I35-J35
A36: PRJ-034 | B36: Marketing | C36: 34261.88 | D36: 37473.2 | E36: 4186.76 | F36: =SUM(C36:E36) | G36: =F36*'Rates'!$B$3 | H36: =F36*'Rates'!$B$4 | I36: 95677 | J36: =SUM(F36:H36) | K36: =I36-J36
A37: PRJ-035 | B37: Technology | C37: 10108.15 | D37: 14220.81 | E37: 613.93 | F37: =SUM(C37:E37) | G37: =F37*'Rates'!$B$3 | H37: =F37*'Rates'!$B$4 | I37: 30458 | J37: =SUM(F37:H37) | K37: =I37-J37
A38: PRJ-036 | B38: Marketing | C38: 13006.58 | D38: 2860.23 | E38: 2289.96 | F38: =SUM(C38:E38) | G38: =F38*'Rates'!$B$3 | H38: =F38*'Rates'!$B$4 | I38: 21483 | J38: =SUM(F38:H38) | K38: =I38-J38
A39: PRJ-037 | B39: Technology | C39: 64828.75 | D39: 16997.83 | E39: 6514.05 | F39: =SUM(C39:E39) | G39: =F39*'Rates'!$B$3 | H39: =F39*'Rates'!$B$4 | I39: 109956 | J39: =SUM(F39:H39) | K39: =I39-J39
A40: PRJ-038 | B40: Operations | C40: 23050.02 | D40: 14822.97 | E40: 9081.11 | F40: =SUM(C40:E40) | G40: =F40*'Rates'!$B$3 | H40: =F40*'Rates'!$B$4 | I40: 60306 | J40: =SUM(F40:H40) | K40: =I40-J40
A41: PRJ-039 | B41: Marketing | C41: 46805.95 | D41: 20085.54 | E41: 5319.38 | F41: =SUM(C41:E41) | G41: =F41*'Rates'!$B$3 | H41: =F41*'Rates'!$B$4 | I41: 93186 | J41: =SUM(F41:H41) | K41: =I41-J41
A42: PRJ-040 | B42: Operations | C42: 23303.98 | D42: 13387.3 | E42: 5618.45 | F42: =SUM(C42:E42) | G42: =F42*'Rates'!$B$3 | H42: =F42*'Rates'!$B$4 | I42: 52533 | J42: =SUM(F42:H42) | K42: =I42-J42
A43: PRJ-041 | B43: Operations | C43: 42360.66 | D43: 35314.88 | E43: 4311.06 | F43: =SUM(C43:E43) | G43: =F43*'Rates'!$B$3 | H43: =F43*'Rates'!$B$4 | I43: 100004 | J43: =SUM(F43:H43) | K43: =I43-J43
A44: PRJ-042 | B44: Marketing | C44: 18781.54 | D44: 3924.31 | E44: 3113.43 | F44: =SUM(C44:E44) | G44: =F44*'Rates'!$B$3 | H44: =F44*'Rates'!$B$4 | I44: 31843 | J44: =SUM(F44:H44) | K44: =I44-J44
A45: PRJ-043 | B45: Research | C45: 48460.54 | D45: 15973.35 | E45: 5508.7 | F45: =SUM(C45:E45) | G45: =F45*'Rates'!$B$3 | H45: =F45*'Rates'!$B$4 | I45: 83828 | J45: =SUM(F45:H45) | K45: =I45-J45
A46: PRJ-044 | B46: Research | C46: 26605.09 | D46: 25813.11 | E46: 3313.54 | F46: =SUM(C46:E46) | G46: =F46*'Rates'!$B$3 | H46: =F46*'Rates'!$B$4 | I46: 66873 | J46: =SUM(F46:H46) | K46: =I46-J46
... A72: PRJ-070 | B72: Marketing | C72: 40624.25 | D72: 26774.39 | E72: 1914.15 | F72: =SUM(C72:E72) | G72: =F72*'Rates'!$B$3 | H72: =F72*'Rates'!$B$4 | I72: 82910 | J72: =SUM(F72:H72) | K72: =I72-J72
A73: PRJ-071 | B73: Operations | C73: 13648.25 | D73: 10818.2 | E73: 5889.23 | F73: =SUM(C73:E73) | G73: =F73*'Rates'!$B$3 | H73: =F73*'Rates'!$B$4 | I73: 38557 | J73: =F73+G73 | K73: =I73-J73
A74: PRJ-072 | B74: Marketing | C74: 58112.02 | D74: 30140.21 | E74: 2997.4 | F74: =SUM(C74:E74) | G74: =F74*'Rates'!$B$3 | H74: =F74*'Rates'!$B$4 | I74: 117045 | J74: =SUM(F74:H74) | K74: =I74-J74
A75: PRJ-073 | B75: Research | C75: 48384.34 | D75: 8304.41 | E75: 3003.1 | F75: =SUM(C75:E75) | G75: =F75*'Rates'!$B$3 | H75: =F75*'Rates'!$B$4 | I75: 75355 | J75: =SUM(F75:H75) | K75: =I75-J75
A76: PRJ-074 | B76: Operations | C76: 21520.98 | D76: 35041.49 | E76: 6498.7 | F76: =SUM(C76:E76) | G76: =F76*'Rates'!$B$3 | H76: =F76*'Rates'!$B$4 | I76: 77966 | J76: =SUM(F76:H76) | K76: =I76-J76
A77: PRJ-075 | B77: Operations | C77: 9971.29 | D77: 1917.05 | E77: 3783.56 | F77: =SUM(C77:E77) | G77: =F77*'Rates'!$B$3 | H77: =F77*'Rates'!$B$4 | I77: 20148 | J77: =SUM(F77:H77) | K77: =I77-J77
A78: PRJ-076 | B78: Operations | C78: 68670.24 | D78: 35305.83 | E78: 6538.84 | F78: =SUM(C78:E78) | G78: =F78*'Rates'!$B$3 | H78: =F78*'Rates'!$B$4 | I78: 134959 | J78: =SUM(F78:H78) | K78: =I78-J78
A79: PRJ-077 | B79: Operations | C79: 46657.14 | D79: 24066.57 | E79: 8429.91 | F79: =SUM(C79:E79) | G79: =F79*'Rates'!$B$3 | H79: =F79*'Rates'!$B$4 | I79: 95113 | J79: =SUM(F79:H79) | K79: =I79-J79
A80: PRJ-078 | B80: Marketing | C80: 21679.1 | D80: 2100.16 | E80: 8004.78 | F80: =SUM(C80:E80) | G80: =F80*'Rates'!$B$3 | H80: =F80*'Rates'!$B$4 | I80: 40732 | J80: =SUM(F80:H80) | K80: =I80-J80
A81: PRJ-079 | B81: Operations | C81: 27865.57 | D81: 29940.76 | E81: 4076.36 | F81: =SUM(C81:E81) | G81: =F81*'Rates'!$B$3 | H81: =F81*'Rates'!$B$4 | I81: 76600 | J81: =SUM(F81:H81) | K81: =I81-J81
A82: PRJ-080 | B82: Technology | C82: 53534.01 | D82: 36092.76 | E82: 1133.27 | F82: =SUM(C82:E82) | G82: =F82*'Rates'!$B$3 | H82: =F82*'Rates'!$B$4 | I82: 110249 | J82: =SUM(F82:H82) | K82: =I82-J82
A83: PRJ-081 | B83: Technology | C83: 44389.38 | D83: 27816.75 | E83: 1430.43 | F83: =SUM(C83:E83) | G83: =F83*'Rates'!$B$3 | H83: =F83*'Rates'!$B$4 | I83: 93475 | J83: =SUM(F83:H83) | K83: =I83-J83
...

Sheet Summary
A1: Department Summary
A2: Department | B2: Total Cost | C2: Subtotal | D2: Variance
A3: Research | B3: =SUMIF('Projects'!$B$3:$B$162,A3,'Projects'!$J$3:$J$162) | C3: =SUMIF('Projects'!$B$3:$B$162,A3,'Projects'!$F$3:$F$162) | D3: =SUMIF('Projects'!$B$3:$B$162,A3,'Projects'!$K$3:$K$162)
A4: Operations | B4: =SUMIF('Projects'!$B$3:$B$161,A4,'Projects'!$J$3:$J$161) | C4: =SUMIF('Projects'!$B$3:$B$162,A4,'Projects'!$F$3:$F$162) | D4: =SUMIF('Projects'!$B$3:$B$162,A4,'Projects'!$K$3:$K$162)
A5: Marketing | B5: =SUMIF('Projects'!$B$3:$B$162,A5,'Projects'!$J$3:$J$162) | C5: =SUMIF('Projects'!$B$3:$B$162,A5,'Projects'!$E$3:$E$162) | D5: =SUMIF('Projects'!$B$3:$B$162,A5,'Projects'!$K$3:$K$162)
A6: Technology | B6: =SUMIF('Projects'!$B$3:$B$162,A6,'Projects'!$J$3:$J$162) | C6: =SUMIF('Projects'!$B$3:$B$162,A6,'Projects'!$F$3:$F$162) | D6: =SUMIF('Projects'!$B$3:$B$162,A6,'Projects'!$K$3:$K$162)
