Workbook

Sheet Read Me
A1: StructuralGuard Blind Test Workbook
A3: Scenario | B3: Warehouse inventory movements
A4: Random seed | B4: 22047
A5: Generated rows | B5: 180
A6: Purpose | B6: Blind structural-formula anomaly evaluation
A7: Answer location | B7: Stored outside this workbook
A8: Safety | B8: Do not overwrite this source workbook during analysis

Sheet Settings
A1: Assumptions
A2: Parameter | B2: Value
A3: Reorder point | B3: 25
A4: Critical point | B4: 10

Sheet Movements
A1: Warehouse Inventory Movements
A2: Date | B2: SKU | C2: Opening | D2: Received | E2: Shipped | F2: Closing | G2: Balance Check | H2: Stock Status | I2: Inventory Value | J2: Unit Cost
A3: 46245 | B3: SKU-253 | C3: 43 | D3: 31 | E3: 36 | F3: =C3+D3-E3 | G3: =F3-C3-D3+E3 | H3: =IF(F3<'Settings'!$B$3,"REORDER","OK") | I3: =ROUND(F3*J3,2) | J3: 44.07
A4: 46314 | B4: SKU-334 | C4: 145 | D4: 71 | E4: 70 | F4: =C4+D4-E4 | G4: =F4-C4-D4+E4 | H4: =IF(F4<'Settings'!$B$3,"REORDER","OK") | I4: =ROUND(F4*J4,2) | J4: 61.8
A5: 46087 | B5: SKU-359 | C5: 132 | D5: 49 | E5: 28 | F5: =C5+D5-E5 | G5: =F5-C5-D5+E5 | H5: =IF(F5<'Settings'!$B$3,"REORDER","OK") | I5: =ROUND(F5*J5,2) | J5: 87.9
A6: 46104 | B6: SKU-348 | C6: 99 | D6: 68 | E6: 37 | F6: =C6+D6-E6 | G6: =F6-C6-D6+E6 | H6: =IF(F6<'Settings'!$B$3,"REORDER","OK") | I6: =ROUND(F6*J6,2) | J6: 30.2
A7: 46151 | B7: SKU-953 | C7: 48 | D7: 23 | E7: 10 | F7: =C7+D7-E7 | G7: =F7-C7-D7+E7 | H7: =IF(F7<'Settings'!$B$3,"REORDER","OK") | I7: =ROUND(F7*J7,2) | J7: 37.19
A8: 46134 | B8: SKU-217 | C8: 29 | D8: 14 | E8: 28 | F8: =C8+D8-E8 | G8: =F8-C8-D8+E8 | H8: =IF(F8<'Settings'!$B$3,"REORDER","OK") | I8: =ROUND(F8*J8,2) | J8: 60.53
A9: 46226 | B9: SKU-123 | C9: 142 | D9: 12 | E9: 14 | F9: =C9+D9-E9 | G9: =F9-C9-D9+E9 | H9: =IF(F9<'Settings'!$B$3,"REORDER","OK") | I9: =ROUND(F9*J9,2) | J9: 18.42
A10: 46030 | B10: SKU-871 | C10: 90 | D10: 68 | E10: 23 | F10: =C10+D10-E10 | G10: =F10-C10-D10+E10 | H10: =IF(F10<'Settings'!$B$3,"REORDER","OK") | I10: =ROUND(F10*J10,2) | J10: 23.03
A11: 46361 | B11: SKU-535 | C11: 20 | D11: 44 | E11: 27 | F11: =C11+D11-E11 | G11: =F11-C11-D11+E11 | H11: =IF(F11<'Settings'!$B$3,"REORDER","OK") | I11: =ROUND(F11*J11,2) | J11: 80.68
A12: 46026 | B12: SKU-518 | C12: 128 | D12: 53 | E12: 44 | F12: =C12+D12-E12 | G12: =F12-C12-D12+E12 | H12: =IF(F12<'Settings'!$B$3,"REORDER","OK") | I12: =ROUND(F12*J12,2) | J12: 68.78
A13: 46343 | B13: SKU-301 | C13: 90 | D13: 72 | E13: 45 | F13: =C13+D13-E13 | G13: =F13-C13-D13+E13 | H13: =IF(F13<'Settings'!$B$3,"REORDER","OK") | I13: =ROUND(F13*J13,2) | J13: 8.26
A14: 46321 | B14: SKU-436 | C14: 124 | D14: 11 | E14: 24 | F14: =C14+D14-E14 | G14: =F14-C14-D14+E14 | H14: =IF(F14<'Settings'!$B$3,"REORDER","OK") | I14: =ROUND(F14*J14,2) | J14: 87.61
... A30: 46345 | B30: SKU-760 | C30: 159 | D30: 77 | E30: 2 | F30: =C30+D30-E30 | G30: =F30-C30-D30+E30 | H30: =IF(F30<'Settings'!$B$3,"REORDER","OK") | I30: =ROUND(F30*J30,2) | J30: 89.29
A31: 46344 | B31: SKU-815 | C31: 71 | D31: 13 | E31: 63 | F31: =C31-E31 | G31: =F31-C31-D31+E31 | H31: =IF(F31<'Settings'!$B$3,"REORDER","OK") | I31: =ROUND(F31*J31,2) | J31: 32.73
A32: 46343 | B32: SKU-472 | C32: 42 | D32: 39 | E32: 36 | F32: =C32-E32 | G32: =F32-C32-D32+E32 | H32: =IF(F32<'Settings'!$B$3,"REORDER","OK") | I32: =ROUND(F32*J32,2) | J32: 35.91
A33: 46136 | B33: SKU-647 | C33: 168 | D33: 35 | E33: 55 | F33: =C33-E33 | G33: =F33-C33-D33+E33 | H33: =IF(F33<'Settings'!$B$3,"REORDER","OK") | I33: =ROUND(F33*J33,2) | J33: 66.39
A34: 46288 | B34: SKU-474 | C34: 75 | D34: 13 | E34: 57 | F34: =C34-E34 | G34: =F34-C34-D34+E34 | H34: =IF(F34<'Settings'!$B$3,"REORDER","OK") | I34: =ROUND(F34*J34,2) | J34: 83.14
A35: 46190 | B35: SKU-522 | C35: 103 | D35: 24 | E35: 23 | F35: =C35-E35 | G35: =F35-C35-D35+E35 | H35: =IF(F35<'Settings'!$B$3,"REORDER","OK") | I35: =ROUND(F35*J35,2) | J35: 44.89
A36: 46379 | B36: SKU-479 | C36: 56 | D36: 58 | E36: 24 | F36: =C36-E36 | G36: =F36-C36-D36+E36 | H36: =IF(F36<'Settings'!$B$3,"REORDER","OK") | I36: =ROUND(F36*J36,2) | J36: 41.46
A37: 46149 | B37: SKU-753 | C37: 106 | D37: 31 | E37: 31 | F37: =C37-E37 | G37: =F37-C37-D37+E37 | H37: =IF(F37<'Settings'!$B$3,"REORDER","OK") | I37: =ROUND(F37*J37,2) | J37: 54
A38: 46143 | B38: SKU-420 | C38: 148 | D38: 75 | E38: 16 | F38: =C38-E38 | G38: =F38-C38-D38+E38 | H38: =IF(F38<'Settings'!$B$3,"REORDER","OK") | I38: =ROUND(F38*J38,2) | J38: 48.29
A39: 46307 | B39: SKU-154 | C39: 148 | D39: 60 | E39: 53 | F39: =C39-E39 | G39: =F39-C39-D39+E39 | H39: =IF(F39<'Settings'!$B$3,"REORDER","OK") | I39: =ROUND(F39*J39,2) | J39: 41.35
A40: 46204 | B40: SKU-455 | C40: 112 | D40: 54 | E40: 44 | F40: =C40-E40 | G40: =F40-C40-D40+E40 | H40: =IF(F40<'Settings'!$B$3,"REORDER","OK") | I40: =ROUND(F40*J40,2) | J40: 37.58
A41: 46057 | B41: SKU-156 | C41: 65 | D41: 10 | E41: 29 | F41: =C41-E41 | G41: =F41-C41-D41+E41 | H41: =IF(F41<'Settings'!$B$3,"REORDER","OK") | I41: =ROUND(F41*J41,2) | J41: 55.15
A42: 46351 | B42: SKU-734 | C42: 115 | D42: 51 | E42: 9 | F42: =C42-E42 | G42: =F42-C42-D42+E42 | H42: =IF(F42<'Settings'!$B$3,"REORDER","OK") | I42: =ROUND(F42*J42,2) | J42: 28.08
... A50: 46363 | B50: SKU-937 | C50: 103 | D50: 24 | E50: 4 | F50: =C50-E50 | G50: =F50-C50-D50+E50 | H50: =IF(F50<'Settings'!$B$3,"REORDER","OK") | I50: =ROUND(F50*J50,2) | J50: 30.58
A51: 46120 | B51: SKU-416 | C51: 171 | D51: 28 | E51: 25 | F51: =C51+D51-E51 | G51: =F51-C51-D51+E51 | H51: =IF(F51<'Settings'!$B$3,"REORDER","OK") | I51: =ROUND(F51*J51,2) | J51: 85.17
A52: 46122 | B52: SKU-277 | C52: 127 | D52: 0 | E52: 45 | F52: =C52+D52-E52 | G52: =F52-C52-D52+E52 | H52: =IF(F52<'Settings'!$B$3,"REORDER","OK") | I52: =ROUND(F52*J52,2) | J52: 82.9
A53: 46278 | B53: SKU-801 | C53: 92 | D53: 69 | E53: 58 | F53: =C53+D53-E53 | G53: =F53-C53-D53+E53 | H53: =IF(F53<'Settings'!$B$3,"REORDER","OK") | I53: =ROUND(F53*J53,2) | J53: 37.05
A54: 46374 | B54: SKU-155 | C54: 95 | D54: 45 | E54: 69 | F54: =C54+D54-E54 | G54: =F54-C54-D54+E54 | H54: =IF(F54<'Settings'!$B$3,"REORDER","OK") | I54: =ROUND(F54*J54,2) | J54: 10.47
A55: 46338 | B55: SKU-379 | C55: 162 | D55: 10 | E55: 49 | F55: =C55+D55-E55 | G55: =F55-C55-D55+E55 | H55: =IF(F55<'Settings'!$B$3,"REORDER","OK") | I55: =ROUND(F55*J55,2) | J55: 42.96
A56: 46273 | B56: SKU-591 | C56: 69 | D56: 44 | E56: 14 | F56: =C56+D56-E56 | G56: =F56-C56-D56+E56 | H56: =IF(F56<'Settings'!$B$3,"REORDER","OK") | I56: =ROUND(F56*J56,2) | J56: 14.31
A57: 46312 | B57: SKU-364 | C57: 51 | D57: 50 | E57: 47 | F57: =C57+D57-E57 | G57: =F57-C57-D57+E57 | H57: =IF(F57<'Settings'!$B$3,"REORDER","OK") | I57: =ROUND(F57*J57,2) | J57: 26.69
A58: 46260 | B58: SKU-420 | C58: 127 | D58: 52 | E58: 2 | F58: =C58+D58-E58 | G58: =F58-C58-D58+E58 | H58: =IF(F58<'Settings'!$B$3,"REORDER","OK") | I58: =ROUND(F58*J58,2) | J58: 46.43
A59: 46101 | B59: SKU-264 | C59: 129 | D59: 30 | E59: 42 | F59: =C59+D59-E59 | G59: =F59-C59-D59+E59 | H59: =IF(F59<'Settings'!$B$3,"REORDER","OK") | I59: =ROUND(F59*J59,2) | J59: 28.19
A60: 46024 | B60: SKU-563 | C60: 141 | D60: 52 | E60: 22 | F60: =C60+D60-E60 | G60: =F60-C60-D60+E60 | H60: =IF(F60<'Settings'!$B$3,"REORDER","OK") | I60: =ROUND(F60*J60,2) | J60: 75.74
A61: 46286 | B61: SKU-811 | C61: 99 | D61: 24 | E61: 4 | F61: =C61+D61-E61 | G61: =F61-C61-D61+E61 | H61: =IF(F61<'Settings'!$B$3,"REORDER","OK") | I61: =ROUND(F61*J61,2) | J61: 44.86
A62: 46083 | B62: SKU-677 | C62: 48 | D62: 18 | E62: 2 | F62: =C62+D62-E62 | G62: =F62-C62-D62+E62 | H62: =IF(F62<'Settings'!$B$3,"REORDER","OK") | I62: =ROUND(F62*J62,2) | J62: 49.41
...
