Workbook

Sheet Read Me
A1: StructuralGuard Blind Test Workbook
A3: Scenario | B3: SaaS customer revenue
A4: Random seed | B4: 55099
A5: Generated rows | B5: 200
A6: Purpose | B6: Blind structural-formula anomaly evaluation
A7: Answer location | B7: Stored outside this workbook
A8: Safety | B8: Do not overwrite this source workbook during analysis

Sheet Assumptions
A1: Assumptions
A2: Parameter | B2: Value
A3: Months per year | B3: 12
A4: Support rate | B4: 0.05

Sheet Customers
A1: SaaS Customer Revenue
A2: Customer | B2: Plan | C2: Seats | D2: Unit Price | E2: Discount | F2: MRR | G2: ARR | H2: Support Cost | I2: Net ARR | J2: MRR per Seat
A3: CUS-0001 | B3: Enterprise | C3: 8 | D3: 79 | E3: 0 | F3: =ROUND(C3*D3*(1-E3),2) | G3: =F3*'Assumptions'!$B$3 | H3: =G3*'Assumptions'!$B$4 | I3: =G3-H3 | J3: =IF(C3=0,0,ROUND(F3/C3,2))
A4: CUS-0002 | B4: Growth | C4: 44 | D4: 9 | E4: 0.15 | F4: =ROUND(C4*D4*(1-E4),2) | G4: =F4*'Assumptions'!$B$3 | H4: =G4*'Assumptions'!$B$4 | I4: =G4-H4 | J4: =IF(C4=0,0,ROUND(F4/C4,2))
A5: CUS-0003 | B5: Starter | C5: 23 | D5: 39 | E5: 0.05 | F5: =ROUND(C5*D5*(1-E5),2) | G5: =F5*'Assumptions'!$B$3 | H5: =G5*'Assumptions'!$B$4 | I5: =G5-H5 | J5: =IF(C5=0,0,ROUND(F5/C5,2))
A6: CUS-0004 | B6: Enterprise | C6: 2 | D6: 39 | E6: 0.05 | F6: =ROUND(C6*D6*(1-E6),2) | G6: =F6*'Assumptions'!$B$3 | H6: =G6*'Assumptions'!$B$4 | I6: =G6-H6 | J6: =IF(C6=0,0,ROUND(F6/C6,2))
A7: CUS-0005 | B7: Growth | C7: 37 | D7: 19 | E7: 0.05 | F7: =ROUND(C7*D7*(1-E7),2) | G7: =F7*'Assumptions'!$B$3 | H7: =G7*'Assumptions'!$B$4 | I7: =G7-H7 | J7: =IF(C7=0,0,ROUND(F7/C7,2))
A8: CUS-0006 | B8: Enterprise | C8: 93 | D8: 79 | E8: 0 | F8: =ROUND(C8*D8*(1-E8),2) | G8: =F8*'Assumptions'!$B$3 | H8: =G8*'Assumptions'!$B$4 | I8: =G8-H8 | J8: =IF(C8=0,0,ROUND(F8/C8,2))
A9: CUS-0007 | B9: Enterprise | C9: 112 | D9: 39 | E9: 0.15 | F9: =ROUND(C9*D9*(1-E9),2) | G9: =F9*'Assumptions'!$B$3 | H9: =G9*'Assumptions'!$B$4 | I9: =G9-H9 | J9: =IF(C9=0,0,ROUND(F9/C9,2))
A10: CUS-0008 | B10: Starter | C10: 17 | D10: 19 | E10: 0.05 | F10: =ROUND(C10*D10*(1-E10),2) | G10: =F10*'Assumptions'!$B$3 | H10: =G10*'Assumptions'!$B$4 | I10: =G10-H10 | J10: =IF(C10=0,0,ROUND(F10/C10,2))
A11: CUS-0009 | B11: Starter | C11: 139 | D11: 39 | E11: 0.05 | F11: =ROUND(C11*D11*(1-E11),2) | G11: =F11*'Assumptions'!$B$3 | H11: =G11*'Assumptions'!$B$4 | I11: =G11-H11 | J11: =IF(C11=0,0,ROUND(F11/C11,2))
A12: CUS-0010 | B12: Starter | C12: 13 | D12: 39 | E12: 0.1 | F12: =ROUND(C12*D12*(1-E12),2) | G12: =F12*'Assumptions'!$B$3 | H12: =G12*'Assumptions'!$B$4 | I12: =G12-H12 | J12: =IF(C12=0,0,ROUND(F12/C12,2))
A13: CUS-0011 | B13: Starter | C13: 73 | D13: 39 | E13: 0.05 | F13: =ROUND(C13*D13*(1-E13),2) | G13: =F13*'Assumptions'!$B$3 | H13: =G13*'Assumptions'!$B$4 | I13: =G13-H13 | J13: =IF(C13=0,0,ROUND(F13/C13,2))
A14: CUS-0012 | B14: Enterprise | C14: 57 | D14: 9 | E14: 0.1 | F14: =ROUND(C14*D14*(1-E14),2) | G14: =F14*'Assumptions'!$B$3 | H14: =G14*'Assumptions'!$B$4 | I14: =G14-H14 | J14: =IF(C14=0,0,ROUND(F14/C14,2))
... A35: CUS-0033 | B35: Starter | C35: 60 | D35: 39 | E35: 0.1 | F35: =ROUND(C35*D35*(1-E35),2) | G35: =F35*'Assumptions'!$B$3 | H35: =G35*'Assumptions'!$B$4 | I35: =G35-H35 | J35: =IF(C35=0,0,ROUND(F35/C35,2))
A36: CUS-0034 | B36: Enterprise | C36: 109 | D36: 9 | E36: 0 | F36: =ROUND(C36*D36*(1-E36),2) | G36: =F36*'Assumptions'!$B$3 | H36: =G36*'Assumptions'!$B$4 | I36: =ROUND(F36*G36*(1+H36),2) | J36: =IF(C36=0,0,ROUND(F36/C36,2))
A37: CUS-0035 | B37: Growth | C37: 49 | D37: 79 | E37: 0.1 | F37: =ROUND(C37*D37*(1-E37),2) | G37: =F37*'Assumptions'!$B$3 | H37: =G37*'Assumptions'!$B$4 | I37: =ROUND(F37*G37*(1+H37),2) | J37: =IF(C37=0,0,ROUND(F37/C37,2))
A38: CUS-0036 | B38: Starter | C38: 127 | D38: 39 | E38: 0.05 | F38: =ROUND(C38*D38*(1-E38),2) | G38: =F38*'Assumptions'!$B$3 | H38: =G38*'Assumptions'!$B$4 | I38: =ROUND(F38*G38*(1+H38),2) | J38: =IF(C38=0,0,ROUND(F38/C38,2))
A39: CUS-0037 | B39: Enterprise | C39: 81 | D39: 39 | E39: 0.1 | F39: =ROUND(C39*D39*(1-E39),2) | G39: =F39*'Assumptions'!$B$3 | H39: =G39*'Assumptions'!$B$4 | I39: =ROUND(F39*G39*(1+H39),2) | J39: =IF(C39=0,0,ROUND(F39/C39,2))
A40: CUS-0038 | B40: Starter | C40: 128 | D40: 19 | E40: 0 | F40: =ROUND(C40*D40*(1-E40),2) | G40: =F40*'Assumptions'!$B$3 | H40: =G40*'Assumptions'!$B$4 | I40: =ROUND(F40*G40*(1+H40),2) | J40: =IF(C40=0,0,ROUND(F40/C40,2))
A41: CUS-0039 | B41: Growth | C41: 49 | D41: 79 | E41: 0.15 | F41: =ROUND(C41*D41*(1-E41),2) | G41: =F41*'Assumptions'!$B$3 | H41: =G41*'Assumptions'!$B$4 | I41: =ROUND(F41*G41*(1+H41),2) | J41: =IF(C41=0,0,ROUND(F41/C41,2))
A42: CUS-0040 | B42: Enterprise | C42: 65 | D42: 9 | E42: 0.15 | F42: =ROUND(C42*D42*(1-E42),2) | G42: =F42*'Assumptions'!$B$3 | H42: =G42*'Assumptions'!$B$4 | I42: =ROUND(F42*G42*(1+H42),2) | J42: =IF(C42=0,0,ROUND(F42/C42,2))
A43: CUS-0041 | B43: Growth | C43: 31 | D43: 19 | E43: 0.15 | F43: =ROUND(C43*D43*(1-E43),2) | G43: =F43*'Assumptions'!$B$3 | H43: =G43*'Assumptions'!$B$4 | I43: =ROUND(F43*G43*(1+H43),2) | J43: =IF(C43=0,0,ROUND(F43/C43,2))
A44: CUS-0042 | B44: Enterprise | C44: 64 | D44: 39 | E44: 0.15 | F44: =ROUND(C44*D44*(1-E44),2) | G44: =F44*'Assumptions'!$B$3 | H44: =G44*'Assumptions'!$B$4 | I44: =ROUND(F44*G44*(1+H44),2) | J44: =IF(C44=0,0,ROUND(F44/C44,2))
A45: CUS-0043 | B45: Starter | C45: 4 | D45: 39 | E45: 0.15 | F45: =ROUND(C45*D45*(1-E45),2) | G45: =F45*'Assumptions'!$B$3 | H45: =G45*'Assumptions'!$B$4 | I45: =ROUND(F45*G45*(1+H45),2) | J45: =IF(C45=0,0,ROUND(F45/C45,2))
A46: CUS-0044 | B46: Enterprise | C46: 148 | D46: 9 | E46: 0.05 | F46: =ROUND(C46*D46*(1-E46),2) | G46: =F46*'Assumptions'!$B$3 | H46: =G46*'Assumptions'!$B$4 | I46: =ROUND(F46*G46*(1+H46),2) | J46: =IF(C46=0,0,ROUND(F46/C46,2))
A47: CUS-0045 | B47: Enterprise | C47: 147 | D47: 9 | E47: 0.15 | F47: =ROUND(C47*D47*(1-E47),2) | G47: =F47*'Assumptions'!$B$3 | H47: =G47*'Assumptions'!$B$4 | I47: =ROUND(F47*G47*(1+H47),2) | J47: =IF(C47=0,0,ROUND(F47/C47,2))
... A55: CUS-0053 | B55: Growth | C55: 13 | D55: 39 | E55: 0.15 | F55: =ROUND(C55*D55*(1-E55),2) | G55: =F55*'Assumptions'!$B$3 | H55: =G55*'Assumptions'!$B$4 | I55: =ROUND(F55*G55*(1+H55),2) | J55: =IF(C55=0,0,ROUND(F55/C55,2))
A56: CUS-0054 | B56: Enterprise | C56: 126 | D56: 79 | E56: 0.1 | F56: =ROUND(C56*D56*(1-E56),2) | G56: =F56*'Assumptions'!$B$3 | H56: =G56*'Assumptions'!$B$4 | I56: =G56-H56 | J56: =IF(C56=0,0,ROUND(F56/C56,2))
A57: CUS-0055 | B57: Enterprise | C57: 3 | D57: 9 | E57: 0.05 | F57: =ROUND(C57*D57*(1-E57),2) | G57: =F57*'Assumptions'!$B$3 | H57: =G57*'Assumptions'!$B$4 | I57: =G57-H57 | J57: =IF(C57=0,0,ROUND(F57/C57,2))
A58: CUS-0056 | B58: Starter | C58: 27 | D58: 79 | E58: 0.1 | F58: =ROUND(C58*D58*(1-E58),2) | G58: =F58*'Assumptions'!$B$3 | H58: =G58*'Assumptions'!$B$4 | I58: =G58-H58 | J58: =IF(C58=0,0,ROUND(F58/C58,2))
A59: CUS-0057 | B59: Starter | C59: 109 | D59: 19 | E59: 0.05 | F59: =ROUND(C59*D59*(1-E59),2) | G59: =F59*'Assumptions'!$B$3 | H59: =G59*'Assumptions'!$B$4 | I59: =G59-H59 | J59: =IF(C59=0,0,ROUND(F59/C59,2))
A60: CUS-0058 | B60: Starter | C60: 70 | D60: 79 | E60: 0.05 | F60: =ROUND(C60*D60*(1-E60),2) | G60: =F60*'Assumptions'!$B$3 | H60: =G60*'Assumptions'!$B$4 | I60: =G60-H60 | J60: =IF(C60=0,0,ROUND(F60/C60,2))
A61: CUS-0059 | B61: Enterprise | C61: 54 | D61: 19 | E61: 0.05 | F61: =ROUND(C61*D61*(1-E61),2) | G61: =F61*'Assumptions'!$B$3 | H61: =G61*'Assumptions'!$B$4 | I61: =G61-H61 | J61: =IF(C61=0,0,ROUND(F61/C61,2))
A62: CUS-0060 | B62: Enterprise | C62: 50 | D62: 19 | E62: 0.05 | F62: =ROUND(C62*D62*(1-E62),2) | G62: =F62*'Assumptions'!$B$3 | H62: =G62*'Assumptions'!$B$4 | I62: =G62-H62 | J62: =IF(C62=0,0,ROUND(F62/C62,2))
A63: CUS-0061 | B63: Starter | C63: 26 | D63: 19 | E63: 0.15 | F63: =ROUND(C63*D63*(1-E63),2) | G63: =F63*'Assumptions'!$B$3 | H63: =G63*'Assumptions'!$B$4 | I63: =G63-H63 | J63: =IF(C63=0,0,ROUND(F63/C63,2))
A64: CUS-0062 | B64: Enterprise | C64: 16 | D64: 39 | E64: 0.1 | F64: =ROUND(C64*D64*(1-E64),2) | G64: =F64*'Assumptions'!$B$3 | H64: =G64*'Assumptions'!$B$4 | I64: =G64-H64 | J64: =IF(C64=0,0,ROUND(F64/C64,2))
A65: CUS-0063 | B65: Growth | C65: 15 | D65: 9 | E65: 0.05 | F65: =ROUND(C65*D65*(1-E65),2) | G65: =F65*'Assumptions'!$B$3 | H65: =G65*'Assumptions'!$B$4 | I65: =G65-H65 | J65: =IF(C65=0,0,ROUND(F65/C65,2))
A66: CUS-0064 | B66: Growth | C66: 58 | D66: 19 | E66: 0 | F66: =ROUND(C66*D66*(1-E66),2) | G66: =F66*'Assumptions'!$B$3 | H66: =G66*'Assumptions'!$B$4 | I66: =G66-H66 | J66: =IF(C66=0,0,ROUND(F66/C66,2))
A67: CUS-0065 | B67: Growth | C67: 50 | D67: 9 | E67: 0.15 | F67: =ROUND(C67*D67*(1-E67),2) | G67: =F67*'Assumptions'!$B$3 | H67: =G67*'Assumptions'!$B$4 | I67: =G67-H67 | J67: =IF(C67=0,0,ROUND(F67/C67,2))
...

Sheet Plan Summary
A1: Plan Revenue Summary
A2: Plan | B2: Customer Count | C2: Net ARR
A3: Starter | B3: =COUNTIF('Customers'!$B$3:$B$202,A3) | C3: =SUMIF('Customers'!$B$3:$B$202,A3,'Customers'!$I$3:$I$202)
A4: Growth | B4: =COUNTIF('Customers'!$B$3:$B$202,A4) | C4: =SUMIF('Customers'!$B$3:$B$202,A4,'Customers'!$I$3:$I$202)
A5: Enterprise | B5: =COUNTIF('Customers'!$B$3:$B$202,A5) | C5: =SUMIF('Customers'!$B$3:$B$202,A5,'Customers'!$I$3:$I$202)
