Workbook

Sheet Read Me
A1: Air Pollution Control Cost Estimation Spreadsheet
A2: For Refrigerated Surface Condensers
A3: U.S. Environmental Protection Agency
A4: Air Economics Group
A5: Health and Environmental Impacts Division
A6: Office of Air Quality Planning and Standards
A7: (November 2017)
B9: This spreadsheet allows users to estimate the capital and annualized costs for installing and operating refrigerated surface condensers used to control emissions of volatile organic compounds (VOCs) and hazardous air pollutants (HAP) from industrial waste gas streams. Refrigerated condensers lower the temperature of the waste stream to the temperature at which the volatile components of a vapor mixture change from the gas to liquid phase. The basic equipment required for a refrigerated condenser system includes a condenser, a single or multi-stage refrigeration unit, and auxiliary equipment, such as pre-coolers, storage tanks for recovered condensate, blowers and piping. Pre-coolers are used where the waste stream contains a water vapor or a VOC that has a high freezing point. Refrigerated condensers are typically used to control waste streams with VOC concentrations above 5,000 ppmv. The condensate can be collected for reuse or sale.
B11: The calculation methodologies used in this spreadsheet are those presented in the U.S. EPA's Air Pollution Control Cost Manual. This spreadsheet is intended to be used in combination with the Control Cost Manual. For a detailed description of the technology and cost methodology, see Section 3.1 (VOC Recapture Controls), Chapter 2 (Refrigerated Condensers) of the Air Pollution Control Cost Manual (as updated in 2017). Additional control technologies may be necessary for some industrial waste gas streams. Costs for additional control technologies can be estimated using the methods provided in other chapters of the cost manual. A copy of the Control Cost Manual is available on the U.S. EPA's "Technology Transfer Network" website at: https://www.epa.gov/economic-and-cost-analysis-air-pollution-regulations/cost-reports-and-guidance-air-pollution.
B13: The spreadsheet can be used to estimate capital and annualized costs for refrigerated surface condensers only. The methodology assumes a two-component mixture of VOC and air, where the emission stream is free of moisture. The methodology is designed to provide study-level cost estimates. Actual costs, particularly those for installation, can deviate significantly from the costs generated using this spreadsheet due to site conditions. Units of measures in this spreadsheet are English.
B16: Instructions
B17: Step 1: Please select the Data Inputs tab and click on the Reset Form button. This will reset the values on the Data Inputs tab.
B18: Step 2: Use the drop down menu on the Data Inputs tab to select the condenser type from the drop-down list: packaged condenser, custom condenser, or gasoline vapor recovery system.
B19: Step 3: Complete all of the yellow data entry cells on the Data Inputs tab. Many of the fields are pre-populated with default values. Where possible, replace default values provided with site-specific values in accordance with the recommendations provided in the Control Cost Manual. Use of actual values other than the default values in this spreadsheet is recommended; however, sources for all values used should be appropriately documented. The molecular weight, heat capacity, enthalpy of condensation, boiling point and Antonine constants for many commonly used VOCs are provided in Appendix A of Section 3.1 (VOC Recapture Controls), Chapter 2 (Refrigerated Condensers) of the Air Pollution Control Cost Manual (as updated in 2017).
B20: Step 4: Once all of the data fields are complete, select the Design Parameters tab to see the calculated design parameters for your condenser. Select the Cost Estimate tab to view the estimated installation and operation costs for the condenser.

Sheet Data Inputs
C1: Data Inputs | L1: 4
M2: Packaged Condenser System
A3: Is the condenser a packaged, custom or gasoline vapor recovery system? | M3: Custom Condenser System
M4: Gasoline Vapor Recovery System
A5: Enter the design data for the proposed condenser:
A7: Number of operating hours per year and per day (Ɵs) | B7: 2080 | C7: hours/year | D7: 8 | E7: hours/day
A8: Volumetric flow rate of the waste stream (Qin) | B8: 100 | C8: ="scfm (at 77 °F; 1 atm)"&(IF(B8=100,"*","")) -> scfm (at 77 °F; 1 atm)* | D8: =IF(B8=100,"* 100 scfm is a default volumetric flow rate. User should enter actual value, if known."," ") -> * 100 scfm is a default volumetric flow rate. User should enter actual value, if known.
A9: Inlet stream temperature (Tin) | B9: 86 | C9: ="°F"&(IF(B9=86,"*","")) -> °F* | D9: =IF(B9=86,"* 86 °F is a default inlet stream temperature. User should enter actual value, if known."," ") -> * 86 °F is a default inlet stream temperature. User should enter actual value, if known.
A10: Required VOC removal efficiency (η) | B10: 90 | C10: ="%"&(IF(B10=90, "*","")) -> %* | D10: =IF(B10=90,"* 90% is a default control efficiency. User should enter actual value, if known."," ") -> * 90% is a default control efficiency. User should enter actual value, if known. | M10: =B10/100 -> 0.9
A11: Specific heat of the coolant (Cp,cool) | B11: 0.65 | C11: ="Btu/lb-mole-°F"&IF(B11=0.65,"*","") -> Btu/lb-mole-°F* | D11: =IF(B11=0.65,"* 0.65 Btu/lb-mole-°F is a default value. User should enter actual value, if known."," ") -> * 0.65 Btu/lb-mole-°F is a default value. User should enter actual value, if known.
A12: Estimated equipment life (n) | B12: 15 | C12: ="Years"&IF(B12=15,"*","") -> Years* | D12: =IF(B12=15,"* 15 years is a default equipment life. User should enter actual value, if known."," ") -> * 15 years is a default equipment life. User should enter actual value, if known.
A13: Overall heat transfer coefficient (U) | B13: 20 | C13: ="Btu/hour-ft²-°F"&IF(B13=20,"*","") -> Btu/hour-ft²-°F* | D13: =IF(B13=20,"* 20 Btu/hour-ft²-°F is a default heat transfer coefficient. User should enter actual value, if known."," ") -> * 20 Btu/hour-ft²-°F is a default heat transfer coefficient. User should enter actual value, if known.
A14: Mechanical efficiency of compressor (ηcomp) | B14: 85 | C14: ="%"&IF(B14=85,"*","") -> %* | D14: =IF(B14=85,"* 85% is a default value. User should enter actual value, if known."," ") -> * 85% is a default value. User should enter actual value, if known.
A16: Enter the Characteristics of the VOC/HAP:
A18: Name of VOC/HAP | B18: Benzene
A19: ="Molecular Weight of "&B18 &" (MW)" -> Molecular Weight of Benzene (MW) | B19: 78.11 | C19: lb./mole | E19: Note:
A20: ="Density of "&B18 -> Density of Benzene | B20: 7.31 | C20: lb./gallon | E20: Values for several common compounds are included on the Table A (Physical Properties) and Table B (Antoine Constants) tabs.
A21: ="Heat Capacity of "&B18&" (Cp,voc)" -> Heat Capacity of Benzene (Cp,voc) | B21: 32.51 | C21: Btu/lb.-mole-°F
A22: ="Heat of Condensation of "&B18&" (ΔHref)" -> Heat of Condensation of Benzene (ΔHref) | B22: 13210 | C22: Btu/lb.-mole
A23: ="Boiling Point of "&B18 -> Boiling Point of Benzene | B23: 176 | C23: °F
A24: ="Antoine Equation Constants for "&B18 -> Antoine Equation Constants for Benzene | B24: A | C24: B | D24: C
B25: 6.90565 | C25: 1211.033 | D25: 220.79
A26: ="Critical Temperature for "&B18 -> Critical Temperature for Benzene | B26: 1012 | C26: °R
A27: ="Volume Fraction of "&B18&" in waste stream entering the condenser (Yvoc,in)" -> Volume Fraction of Benzene in waste stream entering the condenser (Yvoc,in) | B27: 0.25
A29: Enter the cost data for the condenser:
A31: Electricity (Costelect) | B31: 0.0641 | C31: ="per kWh"&IF(B31=0.0641, "*","") -> per kWh* | D31: =IF(B31=0.0641,"* $0.0641/kWh is a default value. User should enter actual value, if known.","") -> * $0.0641/kWh is a default value. User should enter actual value, if known.
A32: Operator Labor Rate | B32: 26.61 | C32: ="per hour"&IF(B32=26.61,"*","") -> per hour* | D32: =IF(B32=26.61,"* $26.61/hour is a default value. User should enter actual value, if known.","") -> * $26.61/hour is a default value. User should enter actual value, if known.
A33: Maintenance Labor Rate | B33: 27.4 | C33: ="per hour"&IF(B33=27.4,"*","") -> per hour* | D33: =IF(B33=27.4,"* $27.40/hour is a default value. User should enter actual value, if known.","") -> * $27.40/hour is a default value. User should enter actual value, if known.
A34: Re-Sale Value of Recovered VOC (Credit) | B34: 0.28 | C34: per lb
A35: Contingency Factor (CF) | B35: 10 | C35: ="percent"&IF(B35=10,"*","") -> percent* | D35: =IF(B35=10,"* 10 percent is a default value. The contingency factor should be between 5 and 15 percent.","") -> * 10 percent is a default value. The contingency factor should be between 5 and 15 percent.
A36: If known, enter any additional costs for site preparation and building construction/modification:
A37: Site Preparation (SP) = | B37: 0 | C37: =IF(B37=0, "* Default value. User should enter actual value, if known."," ") -> * Default value. User should enter actual value, if known.
A38: Buildings (Bldg) = | B38: 0 | C38: =IF(B38=0, "* Default value. User should enter actual value, if known."," ") -> * Default value. User should enter actual value, if known.
A39: Equipment Costs for auxiliary equipment for custom condenser systems (ECaux) = | B39: 0 | C39: =IF(B39=0, "* Default value. User should enter actual value, if known."," ") -> * Default value. User should enter actual value, if known.
A41: Desired dollar-year | B41: 2016
A42: ="CEPCI* for " & B41 -> CEPCI* for 2016 | B42: 536.4 | C42: =IF(B41=2014," ","Enter the CEPCI value for "&B41) -> Enter the CEPCI value for 2016 | E42: 576.1 | F42: 2014 CEPCI
A43: Annual Interest Rate (i) | B43: 4.25 | C43: =(IF(B43=4.25,"% (Current back prime rate)","% (Default value is 4.25%)")) -> % (Current back prime rate)
A45: * CEPCI is the Chemical Engineering Plant Cost Index. The use of CEPCI in this spreadsheet is not an endorsement of the index for purpose of cost escalation or de-escalation, but is there merely to allow for availability of a well-known cost index to spreadsheet users. Use of other well-known cost indexes (e.g., M&S) is acceptable.
A48: Data Sources for Default Values Used in Calculations:
A50: Data Element | B50: Default Value | C50: Sources for Default Value | E50: If you used your own site-specific values, please reference the source from which the site-specific value was derived. | J50: Recommended data sources for site-specific information
...

Sheet Design Parameters
A1: Design Parameters
A3: The following design parameters for the condenser were calculated based on the values entered on the Data Inputs tab. These values were used to prepare the costs shown on the Cost Estimate tab.
A5: VOC | B5: VOC volume Fraction of waste stream entering the condenser (Yvoc,in) | C5: Heat Capacity (Cp,voc) | D5: Heat of Condensation (ΔHref)
C6: (Btu/lb.-mole-°F) | D6: (Btu/lb.-mole)
A7: =IF('Data Inputs'!B18="", "Not Applicable ", 'Data Inputs'!B18) -> Benzene | B7: ='Data Inputs'!B27 -> 0.25 | C7: ='Data Inputs'!B21 -> 32.51 | D7: ='Data Inputs'!B22 -> 13210
A9: Parameter | B9: Equation | D9: Calculated Value | E9: Units
A10: ="Partial Pressure of "&A7&" VOC in Exit Stream (Pvoc) = " -> Partial Pressure of Benzene VOC in Exit Stream (Pvoc) = | B10: 760 × (Mvoc,out / (Min - Mvoc, recovered)) = | C10: 760 × [Yvoc,in × (1 - η)] / [1 - (η × Yvoc,in)] = | D10: =760*((B7*(1-'Data Inputs'!$M$10))/(1-(B7*'Data Inputs'!$M$10))) -> 24.516129 | E10: mmHg
A11: ="Estimated Condensation Temperature for "&A7&" (Tcon) = " -> Estimated Condensation Temperature for Benzene (Tcon) = | B11: ((B / (A - log (Pvoc))) - C) × 1.8 + 32 = | D11: =IF(B7>0, ((('Data Inputs'!C25)/('Data Inputs'!B25-LOG10($D10))-'Data Inputs'!D25)*1.8+32), 0) -> 29.752241 | E11: °F
A13: Parameter | B13: Equation | C13: Calculated Value | D13: Units | E13: Calculated Value | F13: Units
A14: Quantities of VOC in Inlet and Outlet streams:
A15: Moles of VOC in the inlet stream (Mvoc,in) = | B15: (Qin / 392) × (Yvoc,in) × 60 = | C15: =('Data Inputs'!B8/392)*(B7*60) -> 3.8265306 | D15: lb.-moles/hour
A16: Moles of VOC in the outlet stream (Mvoc,out) = | B16: Mvoc,in × (1 - η) = | C16: =C15*(1-'Data Inputs'!M10) -> 0.38265306 | D16: lb.-moles/hour
A18: Quantity of VOC Recovered:
A19: Moles of VOC Recovered (Mvoc, recovered) = | B19: Mvoc,in × η = | C19: =C15*'Data Inputs'!M10 -> 3.4438776 | D19: lb.-moles/hour
A20: Quantity of VOC Recovered (Wvoc) = | B20: Mvoc, recovered × MWvoc = | C20: =C19*'Data Inputs'!B19 -> 269.00128 | D20: lb./operating hour | E20: =(C20*'Data Inputs'!B7)/2000 -> 279.76133 | F20: Tons/year
A22: Estimated Storage Tank Capacity for Custom Condenser Systems:
A23: Storage Tank Volume (Vtank) = | B23: (Wvoc / ρvoc) × Operating Hours Per Day = | C23: =(C20/'Data Inputs'!B20)*'Data Inputs'!D7 -> 294.39264 | D23: gallons
A25: Calculation of Enthalpy of Condensation:
A26: Critical Temperature for VOC (Tc) = | C26: ='Data Inputs'!B26 -> 1012 | D26: °R
A27: Reference Temperature for Heat of Condensation (T1) = | C27: ='Data Inputs'!B23+459.67 -> 635.67 | D27: °R
A28: Condensation Temperature (T2) = | B28: Tcon + 459.67 = | C28: =D11+459.67 -> 489.42224 | D28: °R
A29: ="Enthalpy of condensation of VOC (ΔHvoc) at "&ROUND(D11,1)&" °F =" -> Enthalpy of condensation of VOC (ΔHvoc) at 29.8 °F = | B29: ΔHref × [(1 - T2 / Tc) / (1 - T1 / Tc)]0.38 = | C29: =D7*((1-C28/C26)/(1-C27/C26))^0.38 -> 14965.251 | D29: Btu/lb.-mole
A31: Calculation of Condenser Heat Load:
A32: Heat capacity of air (Cp, air) = | C32: 6.95 | D32: Btu/lb.-mole-°F @ 77 °F and 1 atm.
A33: Mean Temperature (Tmean) = | B33: (Tin + Tcon) / 2 = | C33: =('Data Inputs'!B9+'Design Parameters'!D11)/2 -> 57.876121 | D33: °F
A34: Enthalpy change associated with the condensed VOC (ΔHcon) = | B34: Mvoc,recovered × [ΔHvoc + Cp,voc (Tin - Tcon)]= | C34: =C19*(C29+(C7*('Data Inputs'!B9-D11))) -> 57836.017 | D34: Btu/hour
A35: Enthalpy change associated with the uncondensed VOC (ΔHuncon) = | B35: Mvoc,out × Cp,voc × (Tin - Tcon) = | C35: =C16*C7*('Data Inputs'!B9-D11) -> 699.72499 | D35: Btu/hour
A36: Enthalpy change associated with the non-condensable air (ΔHnoncon) = | B36: [((Qin / 392) × 60) - Mvoc,in] × Cp,air × (Tin - Tcon) = | C36: =(('Data Inputs'!B8*60/392)-C15)*C32*('Data Inputs'!B9-D11) -> 4487.6241 | D36: Btu/hour
A37: Condenser Heat Load (Hload) = | B37: ΔHcon + ΔHuncon + ΔHnoncon = | C37: =C34+C35+C36 -> 63023.366 | D37: Btu/hour
A39: Calculation of Surface Area:
A40: Temperature of coolant entering the condenser (Tcool,in) = | B40: Tcon - 15 °F = | C40: =D11-15 -> 14.752241 | D40: °F
A41: Temperature of coolant exiting the condenser (Tcool,out) = | B41: Tcool,in + 25 °F = | C41: =C40+25 -> 39.752241 | D41: °F
A42: Logarithmic mean temperature difference (ΔTlm ) = | B42: [(Tin - Tcool,out) - (Tcon -Tcool,in)] | C42: =(('Data Inputs'!B9-'Design Parameters'!C41)-(D11-C40))/(LN(('Data Inputs'!B9-C41)/(D11-'Design Parameters'!C40))) -> 27.752035 | D42: °F
B43: [ln{(Tin - Tcool, out)/(Tcon - Tcool,in)}]
A44: Condenser Surface Area (Acon) = | B44: Hload / (U × ΔTlm) = | C44: =C37/('Data Inputs'!B13*C42) -> 113.54729 | D44: ft²
A46: Calculation of Coolant Flow Rate and Refrigeration Capacity:
A47: Coolant Flow Rate (Wcool) = | B47: Hload / (Cp,cool × (Tcool,out - Tcool,in)) = | C47: =C37/('Data Inputs'!B11*('Design Parameters'!C41-'Design Parameters'!C40)) -> 3878.361 | D47: lb./hour
A48: Refrigeration Capacity (R) = | B48: Hload / 12,000 Btu/ton = | C48: =C37/12000 -> 5.2519472 | D48: Tons/hour
A50: Calculation of Electricity Consumption:
A51: Estimated Electricity Consumption (E) = | B51: 2.7411 × exp(-0.015 × Tcon) = | C51: =2.7411*EXP(-0.015*D11) -> 1.7543101 | D51: kW/ton
...

Sheet Cost Estimate
B1: Cost Estimate | P1: Tcon = | Q1: ='Design Parameters'!D11 -> 29.752241 | R1: R = | S1: ='Design Parameters'!C48 -> 5.2519472
P2: Single | V2: Multi
B3: Capital Costs | P3: Temperature | R3: R Min | S3: R Max | V3: Temperature | X3: R Min | Y3: R Max
C4: =IF('Data Inputs'!L1=1,"Warning! You failed to select a condenser type. Please return to the Data Inputs tab and select a condenser type (packaged, custom or gasoline vapor recovery)."," ")
A5: ="Estimated purchase costs for a "&(IF('Data Inputs'!L1=2,"packaged condenser",IF('Data Inputs'!L1=3,"custom condenser","gasoline vapor recovery system")&" with the following design specifications:")) -> Estimated purchase costs for a gasoline vapor recovery system with the following design specifications: | P5: 35 | Q5: 45 | R5: 85 | S5: 174 | T5: =IF(AND($Q$1>P5,$Q$1<Q5,$S$1>R5,$S$1<S5),1,0) -> 0 | V5: -15 | W5: -5 | X5: 3.5 | Y5: 81 | Z5: =IF(AND($Q$1>V5,$Q$1<W5,$S$1>X5,$S$1<Y5),1,0) -> 0
A6: VOC Controlled/Recovered = | B6: ='Data Inputs'!B18 -> Benzene | P6: 25 | Q6: 35 | R6: 0.63 | S6: 170 | T6: =IF(AND($Q$1>P6,$Q$1<Q6,$S$1>R6,$S$1<S6),1,0) -> 1 | V6: -25 | W6: -15 | X6: 2.92 | Y6: 68 | Z6: =IF(AND($Q$1>V6,$Q$1<W6,$S$1>X6,$S$1<Y6),1,0) -> 0
A7: Refrigeration Capacity (R) = | B7: =ROUND('Design Parameters'!C48,2)&" tons/hour" -> 5.25 tons/hour | P7: 15 | Q7: 25 | R7: 0.71 | S7: 880 | T7: =IF(AND($Q$1>P7,$Q$1<Q7,$S$1>R7,$S$1<S7),1,0) -> 0 | V7: -35 | W7: -25 | X7: 2.42 | Y7: 85 | Z7: =IF(AND($Q$1>V7,$Q$1<W7,$S$1>X7,$S$1<Y7),1,0) -> 0
A8: Condensation Temperature for Waste Stream (Tcon) = | B8: =ROUND('Design Parameters'!D11,0)&" °F" -> 30 °F | P8: 0 | Q8: 15 | R8: 0.44 | S8: 200 | T8: =IF(AND($Q$1>P8,$Q$1<Q8,$S$1>R8,$S$1<S8),1,0) -> 0 | V8: -45 | W8: -35 | X8: 1.92 | Y8: 68 | Z8: =IF(AND($Q$1>V8,$Q$1<W8,$S$1>X8,$S$1<Y8),1,0) -> 0
P9: -5 | Q9: 0 | R9: 0.32 | S9: 133 | T9: =IF(AND($Q$1>P9,$Q$1<Q9,$S$1>R9,$S$1<S9),1,0) -> 0 | V9: -55 | W9: -45 | X9: 1.58 | Y9: 55 | Z9: =IF(AND($Q$1>V9,$Q$1<W9,$S$1>X9,$S$1<Y9),1,0) -> 0
P10: -15 | Q10: -5 | R10: 0.21 | S10: 6.6 | T10: =IF(AND($Q$1>P10,$Q$1<Q10,$S$1>R10,$S$1<S10),1,0) -> 0 | V10: -65 | W10: -55 | X10: 1.25 | Y10: 100 | Z10: =IF(AND($Q$1>V10,$Q$1<W10,$S$1>X10,$S$1<Y10),1,0) -> 0
A11: ="Total Capital Investment (TCI) (in "&'Data Inputs'!B41&" dollars)" -> Total Capital Investment (TCI) (in 2016 dollars) | P11: -25 | Q11: -15 | R11: 0.13 | S11: 200 | T11: =IF(AND($Q$1>P11,$Q$1<Q11,$S$1>R11,$S$1<S11),1,0) -> 0 | V11: -75 | W11: -65 | X11: 1.33 | Y11: 42 | Z11: =IF(AND($Q$1>V11,$Q$1<W11,$S$1>X11,$S$1<Y11),1,0) -> 0
A12: Parameter | B12: Equation | C12: Single Stage | D12: Multi-Stage | E12: Gasoline Vapor Recovery System | V12: -85 | W12: -75 | X12: 1.08 | Y12: 150 | Z12: =IF(AND($Q$1>V12,$Q$1<W12,$S$1>X12,$S$1<Y12),1,0) -> 0
A13: Equipment Costs for Single Stage Refrigeration Unit: | F13: =IF('Data Inputs'!L1=1," ",(IF(Q1<-25,"* A single stage condenser is not appropriate where the Tcon is below -25 °F.",IF(T13=0,"*Estimated equipment cost for the single stage condenser (Ecr) may not be accurate. Values of R and Tcon are outside the applicability range for the ECr cost equation."," ")))) | S13: IF value is 1, then ECR equation is applicable | T13: =SUM(T5:T11) -> 1 | V13: -95 | W13: -85 | X13: 0.83 | Y13: 28 | Z13: =IF(AND($Q$1>V13,$Q$1<W13,$S$1>X13,$S$1<Y13),1,0) -> 0
A14: ="ECr"&(IF(OR(Q1>45, (AND('Cost Estimate'!T13=0,Q1>-25, Q1<45))),"*"," "))&" =" -> ECr = | B14: =IF('Design Parameters'!C48<10,"1.611 × exp[9.83 - 0.014 × Tcon + 0.34 × ln(R)] × ["&'Data Inputs'!B41&" CEPCI / 2014 CEPCI] =", "1.611 × exp[9.26 - 0.007 × Tcon + 0.627 × ln(R)] × ["&'Data Inputs'!B41&" CEPCI / 2014 CEPCI] =") -> 1.611 × exp[9.83 - 0.014 × Tcon + 0.34 × ln(R)] × [2016 CEPCI / 2014 CEPCI] = | C14: =IF(OR('Data Inputs'!L1=1,'Data Inputs'!L1=4),"Not applicable",(IF('Design Parameters'!D11>-30,(IF('Design Parameters'!C48<10,(1.611*EXP(9.83-(0.014*'Design Parameters'!D11)+0.34*LN('Design Parameters'!C48)))*('Data Inputs'!B42/'Data Inputs'!E42),(1.611*EXP(9.26-(0.007*'Design Parameters'!D11)+0.627*LN('Design Parameters'!C48)))*('Data Inputs'!B42/'Data Inputs'!E42))),"Not applicable*"))) -> Not applicable | V14: -105 | W14: -95 | X14: 0.67 | Y14: 22 | Z14: =IF(AND($Q$1>V14,$Q$1<W14,$S$1>X14,$S$1<Y14),1,0) -> 0
A16: Equipment Costs for Multistage Refrigeration Unit: | F16: =IF(AND('Data Inputs'!L1=1,'Data Inputs'!L1=4)," ",(IF(Q1>-5,"* A multi-stage condenser is not necessary where Tcon is above -5 °F.",(IF(Z17=0,"*Estimated equipment cost for the multi-stage condenser, ECr, may not be accurate. Values of R and Tcon are outside the applicability range for the ECr cost equation."," "))))) -> * A multi-stage condenser is not necessary where Tcon is above -5 °F.
A17: ="ECr"&IF(OR(Q1<-105, (AND('Cost Estimate'!Z17=0,Q1<-5, Q1>-105))),"*"," ")&" =" -> ECr = | B17: ="1.611 × exp[9.73 - 0.012 × Tcon + 0.58 × ln(R)] × ["&'Data Inputs'!B41&" CEPCI / 2014 CEPCI] =" -> 1.611 × exp[9.73 - 0.012 × Tcon + 0.58 × ln(R)] × [2016 CEPCI / 2014 CEPCI] = | D17: =IF(OR('Data Inputs'!L1=1,'Data Inputs'!L1=4),"Not applicable", (IF('Design Parameters'!D11<-10,(1.611*EXP(9.73-(0.012*'Design Parameters'!D11)+(0.58*LN('Design Parameters'!C48))))*('Data Inputs'!B42/'Data Inputs'!E42),"Not applicable*"))) -> Not applicable | Y17: IF value is 1, then ECR equation is applicable | Z17: =SUM(Z5:Z14) -> 0
A18: Other Equipment Costs for a Packaged Solvent Recovery System:
A19: ECp = | B19: 0.25 × ECr = | C19: =IF(OR('Data Inputs'!L1=1,'Data Inputs'!L1=4),"Not applicable",(IF(AND('Design Parameters'!D11>-30,'Data Inputs'!L1=2),(0.25*C14),"Not applicable"))) -> Not applicable | D19: =IF(OR('Data Inputs'!L1=1,'Data Inputs'!L1=4),"Not applicable", (IF('Design Parameters'!D11<-10,(0.25*D17),"Not applicable"))) -> Not applicable
A20: Purchase Costs for a Packaged Gasoline Solvent Recovery System:
A21: ECp = | B21: ="1.611 × (4,910 × R + 341,000) × ("&'Data Inputs'!B41&" CEPCI / 2014 CEPCI) =" -> 1.611 × (4,910 × R + 341,000) × (2016 CEPCI / 2014 CEPCI) = | E21: =IF('Data Inputs'!L1=4,(1.611*((4910*'Design Parameters'!C48)+341000))*('Data Inputs'!B42/'Data Inputs'!E42), "Not applicable") -> 550174.48
A23: Purchase Costs for a Custom Condenser (ECcon) = | B23: ="1.611 × (34 × Acon + 3,775) x ["&'Data Inputs'!B41&" CEPCI / 2014 CEPCI] =" -> 1.611 × (34 × Acon + 3,775) x [2016 CEPCI / 2014 CEPCI] = | C23: =IF(OR('Data Inputs'!L1=1,'Data Inputs'!L1=2, 'Data Inputs'!L1=4),"Not applicable", IF('Design Parameters'!D11>-30,(1.611*((34*'Design Parameters'!C44)+3775))*('Data Inputs'!B42/'Data Inputs'!E42),"Not applicable")) -> Not applicable | D23: =IF(OR('Data Inputs'!L1=1,'Data Inputs'!L1=2, 'Data Inputs'!L1=4),"Not applicable",IF('Design Parameters'!D11<-10,(1.611*((34*'Design Parameters'!C44)+3775))*('Data Inputs'!B42/'Data Inputs'!E42),"Not applicable")) -> Not applicable
A26: Purchase Costs for Storage Tanks for a Custom Condenser (ECtank) = | B26: ="1.611 × (2.72 × Vtank + 1,960) × ["&'Data Inputs'!B41&" CEPCI / 2014 CEPCI] =" -> 1.611 × (2.72 × Vtank + 1,960) × [2016 CEPCI / 2014 CEPCI] = | C26: =IF(OR('Data Inputs'!L1=1,'Data Inputs'!L1=2, 'Data Inputs'!L1=4),"Not applicable",IF('Design Parameters'!D11>-30,(1.611*((2.72*'Design Parameters'!C23)+1960))*('Data Inputs'!B42/'Data Inputs'!E42),"Not applicable")) -> Not applicable | D26: =IF(OR('Data Inputs'!L1=1,'Data Inputs'!L1=2,'Data Inputs'!L1=4),"Not applicable", IF('Design Parameters'!D11<-10,(1.611*((2.72*'Design Parameters'!C23)+1960))*('Data Inputs'!B42/'Data Inputs'!E42),"Not applicable")) -> Not applicable
A27: Purchase Costs for Pre-Cooler for Custom Condenser (ECpre) = | B27: =IF('Design Parameters'!C48<10,"1.611 × exp[9.83 - 0.014 × Tcon + 0.34 × ln(R)] × ["&'Data Inputs'!B41&" CEPCI / 2014 CEPCI] =", "1.611 × exp[9.26 - 0.007 × Tcon + 0.627 × ln(R)] × ["&'Data Inputs'!B41&" CEPCI / 2014 CEPCI] =") -> 1.611 × exp[9.83 - 0.014 × Tcon + 0.34 × ln(R)] × [2016 CEPCI / 2014 CEPCI] = | C27: =IF(OR('Data Inputs'!L1=1,'Data Inputs'!L1=2,'Data Inputs'!L1=4),"Not applicable",IF('Design Parameters'!D11>-30,(IF('Design Parameters'!C48<10,(1.611*EXP(9.83-(0.014*'Design Parameters'!D11)+0.34*LN('Design Parameters'!C48)))*('Data Inputs'!B42/'Data Inputs'!E42),(1.611*EXP(9.26-(0.007*'Design Parameters'!D11)+0.627*LN('Design Parameters'!C48)))*('Data Inputs'!B42/'Data Inputs'!E42))),"Not applicable")) -> Not applicable | D27: =IF(OR('Data Inputs'!L1=1,'Data Inputs'!L1=2, 'Data Inputs'!L1=4),"Not applicable", IF('Design Parameters'!D11<-10,(IF('Design Parameters'!C48<10,(1.611*EXP(9.83-(0.014*'Design Parameters'!D11)+0.34*LN('Design Parameters'!C48)))*('Data Inputs'!B42/'Data Inputs'!E42),(1.611*EXP(9.26-(0.007*'Design Parameters'!D11)+0.627*LN('Design Parameters'!C48)))*('Data Inputs'!B42/'Data Inputs'!E42))),"Not applicable")) -> Not applicable
A28: Total Costs for Custom Condenser (A) = | B28: ECr + ECcon + ECtank +ECpre + ECaux = | C28: =IF(OR('Data Inputs'!L1=1,'Data Inputs'!L1=2,'Data Inputs'!L1=4),"Not applicable", IF('Design Parameters'!D11>-30,(C14+C23+C26+C27+'Data Inputs'!B39),"Not applicable")) -> Not applicable | D28: =IF(OR('Data Inputs'!L1=1,'Data Inputs'!L1=2,'Data Inputs'!L1=4),"Not applicable",IF('Design Parameters'!D11<-10,(D17+D23+D26+D27+'Data Inputs'!B39),"Not applicable")) -> Not applicable
A31: Costs for Refrigerated Condenser (A) = | B31: =IF('Data Inputs'!L1=2,"ECp + ECr =", (IF('Data Inputs'!L1=4, "ECp =", " "))) -> ECp = | C31: =IF(OR('Data Inputs'!L1=1,'Data Inputs'!L1=4),"Not applicable",(IF('Design Parameters'!D11>-30, (IF('Data Inputs'!L1=2,(C14+C19), C28)),"Not applicable"))) -> Not applicable | D31: =IF(OR('Data Inputs'!L1=1,'Data Inputs'!L1=4),"Not applicable",IF('Design Parameters'!D11<-10,(IF('Data Inputs'!L1=2, (D17+D19), D28)),"Not applicable")) -> Not applicable | E31: =IF('Data Inputs'!L1=4,'Cost Estimate'!E21, "Not applicable") -> 550174.48
A33: Instrumentation = | B33: 0.10 × A = | C33: =IF(OR('Data Inputs'!L1=1,'Data Inputs'!L1=4),"Not applicable",IF(AND('Design Parameters'!D11>-30,'Data Inputs'!L1=3),(0.1*C31),"Included in A")) -> Not applicable | D33: =IF(OR('Data Inputs'!L1=1,'Data Inputs'!L1=4),"Not applicable",IF(AND('Design Parameters'!D11<-10,'Data Inputs'!L1=3),(0.1*D31),"Included in A")) -> Not applicable | E33: =IF('Data Inputs'!L1=4, "Included in A","Not applicable") -> Included in A
A34: Sales taxes = | B34: 0.03 × A = | C34: =IF(OR('Data Inputs'!L1=1,'Data Inputs'!L1=4),"Not applicable", (IF('Design Parameters'!D11>-30,(0.03*C31),"Not applicable"))) -> Not applicable | D34: =IF(OR('Data Inputs'!L1=1,'Data Inputs'!L1=4),"Not applicable",IF('Design Parameters'!D11<-10,(0.03*D31),"Not applicable")) -> Not applicable | E34: =IF('Data Inputs'!L1=4, 0.03*E31,"Not applicable") -> 16505.234
A35: Freight = | B35: 0.05 × A = | C35: =IF(OR('Data Inputs'!L1=1,'Data Inputs'!L1=4),"Not applicable", (IF('Design Parameters'!D11>-30,(0.05*C31),"Not applicable"))) -> Not applicable | D35: =IF(OR('Data Inputs'!L1=1,'Data Inputs'!L1=4),"Not applicable",IF('Design Parameters'!D11<-10,(0.05*D31),"Not applicable")) -> Not applicable | E35: =IF('Data Inputs'!L1=4,0.05*E31,"Not applicable") -> 27508.724
A37: Total Purchased Equipment Costs (B) = | C37: =IF(OR('Data Inputs'!L1=1,'Data Inputs'!L1=4),"Not applicable",(IF('Design Parameters'!D11>-30,(IF('Data Inputs'!L1=3,SUM(C31:C35),(C31+C34+C35))),"Not applicable "))) -> Not applicable | D37: =IF(OR('Data Inputs'!L1=1,'Data Inputs'!L1=4),"Not applicable",(IF('Design Parameters'!D11<-10,(IF('Data Inputs'!L1=3,SUM(D31:D35),(D31+D34+D35))),"Not applicable"))) -> Not applicable | E37: =IF('Data Inputs'!L1=4, E31+E34+E35, "Not applicable") -> 594188.44
A39: ="Direct Installation Costs (in "&'Data Inputs'!B41&" dollars)" -> Direct Installation Costs (in 2016 dollars)
A40: Parameter | B40: Equation | C40: Single Stage | D40: Multi-Stage | E40: Gasoline Vapor Recovery System
A41: Foundations and Supports = | B41: 0.14 × B = | C41: =IF(OR('Data Inputs'!L1=1,'Data Inputs'!L1=2,'Data Inputs'!L1=4),"Not applicable",(IF('Design Parameters'!D11>-30,(0.14*C$37),"Not applicable"))) -> Not applicable | D41: =IF(OR('Data Inputs'!L1=1,'Data Inputs'!L1=2,'Data Inputs'!L1=4),"Not applicable",IF('Design Parameters'!D11<-10,(0.14*D$37),"Not applicable")) -> Not applicable | E41: Not applicable
A42: Handling and Erection = | B42: 0.08 × B = | C42: =IF(OR('Data Inputs'!L1=1,'Data Inputs'!L1=2,'Data Inputs'!L1=4),"Not applicable", (IF('Design Parameters'!D11>-30,(0.08*C$37),"Not applicable"))) -> Not applicable | D42: =IF(OR('Data Inputs'!L1=1,'Data Inputs'!L1=2,'Data Inputs'!L1=4),"Not applicable",(IF('Design Parameters'!D11<-10,(0.08*D$37),"Not applicable"))) -> Not applicable | E42: Not applicable
A43: Electrical = | B43: 0.08 × B = | C43: =IF(OR('Data Inputs'!L1=1,'Data Inputs'!L1=2,'Data Inputs'!L1=4),"Not applicable", (IF('Design Parameters'!D11>-30,(0.08*C$37),"Not applicable"))) -> Not applicable | D43: =IF(OR('Data Inputs'!L1=1,'Data Inputs'!L1=2,'Data Inputs'!L1=4),"Not applicable",IF('Design Parameters'!D11<-10,(0.08*D$37),"Not applicable")) -> Not applicable | E43: Not applicable
A44: Piping = | B44: 0.02 × B = | C44: =IF(OR('Data Inputs'!L1=1,'Data Inputs'!L1=2,'Data Inputs'!L1=4), "Not applicable",(IF('Design Parameters'!D11>-30,(0.02*C$37),"Not applicable"))) -> Not applicable | D44: =IF(OR('Data Inputs'!L1=1,'Data Inputs'!L1=2,'Data Inputs'!L1=4),"Not applicable",IF('Design Parameters'!D11<-10,(0.02*D$37),"Not applicable")) -> Not applicable | E44: Not applicable
A45: Insulation = | B45: 0.10 × B = | C45: =IF(OR('Data Inputs'!L1=1, 'Data Inputs'!L1=2,'Data Inputs'!L1=4),"Not applicable",(IF('Design Parameters'!D11>-30,(0.1*C$37),"Not applicable"))) -> Not applicable | D45: =IF(OR('Data Inputs'!L1=1, 'Data Inputs'!L1=2,'Data Inputs'!L1=4),"Not applicable",IF('Design Parameters'!D11<-10,(0.1*D$37),"Not applicable")) -> Not applicable | E45: Not applicable
A46: Painting = | B46: 0.01 × B = | C46: =IF(OR('Data Inputs'!L1=1,'Data Inputs'!L1=2,'Data Inputs'!L1=4),"Not applicable", (IF('Design Parameters'!D11>-30,(0.01*C$37),"Not applicable"))) -> Not applicable | D46: =IF(OR('Data Inputs'!L1=1,'Data Inputs'!L1=2,'Data Inputs'!L1=4),"Not applicable",IF('Design Parameters'!D11<-10,(0.01*D$37), "Not applicable")) -> Not applicable | E46: Not applicable
A47: Site Preparation (SP) = | C47: =IF(OR('Data Inputs'!L1=1,'Data Inputs'!L1=4),"Not applicable", (IF('Design Parameters'!D11>-30,('Data Inputs'!B37),"Not applicable"))) -> Not applicable | D47: =IF(OR('Data Inputs'!L1=1,'Data Inputs'!L1=4),"Not applicable",IF('Design Parameters'!D11<-10,('Data Inputs'!B37),"Not applicable")) -> Not applicable | E47: =IF('Data Inputs'!L1=4,('Data Inputs'!D37),"Not applicable") -> 0
A48: Buildings (Bldg) = | C48: =IF(OR('Data Inputs'!L1=1,'Data Inputs'!L1=4),"Not applicable", (IF('Design Parameters'!D11>-30,('Data Inputs'!B38),"Not applicable"))) -> Not applicable | D48: =IF(OR('Data Inputs'!L1=1,'Data Inputs'!L1=4),"Not applicable",IF('Design Parameters'!D11<-10,('Data Inputs'!B38),"Not applicable")) -> Not applicable | E48: =IF('Data Inputs'!L1=4,('Data Inputs'!D38),"Not applicable") -> 0
B50: Total Direct Costs (DC) = B + (0.43 × B) + SP + Bldg = | C50: =IF(OR('Data Inputs'!L1=1,'Data Inputs'!L1=4),"Not applicable", (IF('Design Parameters'!D11>-30,(SUM(C41:C48)+C37),"Not applicable"))) -> Not applicable | D50: =IF(OR('Data Inputs'!L1=1,'Data Inputs'!L1=2,'Data Inputs'!L1=4),"Not applicable",IF('Design Parameters'!D11<-10,(SUM(D41:D48)+D37),"Not applicable")) -> Not applicable | E50: Not applicable
...

Sheet Table A
A1: Table A: Physical Properties for Selected Compounds
A4: Compound | B4: Critical Temp.a (°R) | C4: Boiling Point (°F) | D4: Molecular Weight | E4: Heat of Condensationb (Btu/lb-mole) | F4: Heat Capacityc | G4: State
D5: (lb/lb-mole) | F5: (Btu/lb-mole-°F)
A6: Acetone | B6: 915 | C6: 134 | D6: 58.08 | E6: 12520 | F6: 30.19 | G6: Liquid
F7: 17.81 | G7: Gas
A8: Acetylene | B8: 555 | C8: -119 | D8: 26.02 | E8: 7310 | F8: 10.54 | G8: Gas
A9: Acrylonitrile | B9: 965 | C9: 171 | D9: 53.06 | E9: 14030 | F9: 15.25 | G9: Gas
A10: Aniline | B10: 1258 | C10: 364 | D10: 93.13 | E10: 18240 | F10: 45.87 | G10: Liquid
F11: 25.79 | G11: Gas
A12: Benzene | B12: 1012 | C12: 176 | D12: 78.11 | E12: 13210 | F12: 32.51 | G12: Liquid
A13: Benzonitrile | B13: 1259 | C13: 375 d | D13: 103.12 | E13: 19750 | F13: 26.08 | G13: Gas
A14: Butane | B14: 765 | C14: 31 | D14: 58.12 | E14: 9640 | F14: 23.31 | G14: Gas
A15: Chloroethane | B15: 829 | C15: 54 | D15: 64.52 | E15: 10630 | F15: 14.96 | G15: Gas
A16: Chloroform | B16: 966 | C16: 143 | D16: 119.39 | E16: 12560 | F16: 15.71 | G16: Gas
A17: Chloromethane | B17: 749 | C17: -12 | D17: 50.49 | E17: 9210 | F17: 9.75 | G17: Gas
A18: Cyclobutane | B18: 828 | C18: 55 | D18: 56.1 | E18: 10410 | F18: 17.26 | G18: Gas
A19: Cyclohexane | B19: 996 | C19: 177 | D19: 84.16 | E19: 12910 | F19: 37.03 | G19: Liquid
F20: 25.41 | G20: Gas
A21: Cyclopentane | B21: 921 | C21: 121 | D21: 70.13 | E21: 11750 | F21: 30.81 | G21: Liquid
F22: 19.84 | G22: Gas
A23: Cyclopropane | B23: 716 | C23: -27 | D23: 42.08 | E23: 8650 | F23: 13.29 | G23: Gas
A24: Diethyl ether | B24: 840 | C24: 94 | D24: 74.12 | E24: 11400 | F24: 41.26 | G24: Liquid
F25: 28.57 | G25: Gas
A26: Dimethylamine | B26: 787 | C26: 44 | D26: 45.09 | E26: 11360 | F26: 16.9 | G26: Gas
A27: Ethylbenzene | B27: 1111 | C27: 277 | D27: 106.17 | E27: 15320 | F27: 30.69 d | G27: Gas
A28: Ethylene oxide | B28: 844 | C28: 51 | D28: 44.05 | E28: 10970 | F28: 11.45 | G28: Gas
A29: Heptane | B29: 972 | C29: 209 | D29: 100.12 | E29: 13680 | F29: 53.76 | G29: Liquid
F30: 39.68 | G30: Gas
A31: Hexane | B31: 914 | C31: 156 | D31: 86.18 | E31: 12440 | F31: 46.76 | G31: Liquid
F32: 34.21 | G32: Gas
A33: Methanol | B33: 923 | C33: 148 | D33: 32.04 | E33: 15150 | F33: 19.41 | G33: Liquid
F34: 10.54 | G34: Gas
A35: Octane | B35: 1024 | C35: 258 | D35: 114.23 | E35: 14800 | F35: 45.16 | G35: Gas
A36: Pentane | B36: 845 d | C36: 97 | D36: 72.15 | E36: 11100 | F36: 28.73 | G36: Gas
A37: Toluene | B37: 1065 | C37: 231 | D37: 92.14 | E37: 14290 | F37: 37.53 | G37: Liquid
F38: 24.76 | G38: Gas
A39: o - Xylene | B39: 1135 | C39: 292 | D39: 106.17 | E39: 15880 | F39: 44.49 | G39: Liquid
F40: 31.86 | G40: Gas
A41: m - Xylene | B41: 1111 | C41: 282 | D41: 106.17 | E41: 15360 | F41: 43.82 | G41: Liquid
F42: 30.5 | G42: Gas
...

Sheet Table B
A1: Table B: Antoine Equation Constants for Selected Compoundsa
A3: Compound | B3: Antoine Equation Constants | E3: Valid Temperature Range (°F)
B4: A | C4: B | D4: C
A5: Acetone | B5: 7.11714 | C5: 1210.595 | D5: 229.664 | E5: Liquid
A6: Acetylene | B6: 9.1402 | C6: 1232.6 | D6: 280.9 | E6: -202 to -117
B7: 7.0999 | C7: 711 | D7: 253.4 | E7: -116 to -98
A8: Acrylonitrile | B8: 7.03855 | C8: 1232.53 | D8: 222.47 | E8: -4 to 284
A9: Aniline | B9: 7.3201 | C9: 1731.515 | D9: 206.049 | E9: 216 to 365
A10: Benzene | B10: 9.1064 | C10: 1885.9 | D10: 244.2 | E10: 10 to 37
B11: 6.90565 | C11: 1211.033 | D11: 220.79 | E11: 46 to 217
A12: Benzonitrile | B12: 6.74631 | C12: 1436.72 | D12: 181 | E12: Liquid
A13: n-Butane | B13: 6.80898 | C13: 935.86 | D13: 238.73 | E13: -107 to 66
A14: Chloroethane | B14: 6.98647 | C14: 1030.01 | D14: 238.61 | E14: -69 to 54
A15: Chloroethylene | B15: 6.89117 | C15: 905.01 | D15: 239.48 | E15: -85 to 9
A16: Chloroform | B16: 6.4934 | C16: 929.44 | D16: 196.03 | E16: -31 to 142
A17: Chloromethane | B17: 7.09349 | C17: 948.58 | D17: 249.34 | E17: -103 to 23
A18: Cyanic acid | B18: 7.56859 | C18: 1251.86 | D18: 243.79 | E18: -105 to 21
A19: Cyclobutane | B19: 6.91631 | C19: 1054.54 | D19: 241.37 | E19: -76 to 54
A20: Cyclohexane | B20: 6.8413 | C20: 1201.53 | D20: 222.65 | E20: 68 to 178
A21: Cyclopentane | B21: 6.88676 | C21: 1124.162 | D21: 231.36 | E21: -40 to 162
A22: Cyclopropane | B22: 6.88788 | C22: 856.01 | D22: 246.5 | E22: -130 to -26
A23: Diethyl ether | B23: 6.92032 | C23: 1064.07 | D23: 228.8 | E23: -78 to 68
... A31: Methanol | B31: 7.8975 | C31: 1474.08 | D31: 229.13 | E31: 7 to 149
B32: 7.97328 | C32: 1515.14 | D32: 232.85 | E32: 147 to 230
A33: Octane | B33: 6.91868 | C33: 1351.99 | D33: 209.15 | E33: 66 to 306
A34: Pentane | B34: 6.85296 | C34: 1064.84 | D34: 233.01 | E34: -58 to 136
A35: Toluene | B35: 6.95464 | C35: 1344.8 | D35: 219.48 | E35: 43 to 279
A36: Vinyl acetate | B36: 7.2101 | C36: 1296.13 | D36: 226.66 | E36: 72 to 162
A37: o-Xylene | B37: 6.99891 | C37: 1474.679 | D37: 213.69 | E37: 90 to 342
A38: m-Xylene | B38: 7.00908 | C38: 1462.266 | D38: 215.11 | E38: 82 to 331
A39: p-Xylene | B39: 6.99052 | C39: 1453.43 | D39: 215.31 | E39: 81 to 331
A40: a Reprinted with permission from the 16th edition of Lange's Handbook of Chemistry, Table 2.36 (Speight, 2005).
