Workbook

Sheet Cases
A1: rate=0;type=0;fv=0;pmt | B1: =PMT(0,12,1000,0,0)
A2: rate=0;type=0;fv=0;ppmt=1 | B2: =PPMT(0,1,12,1000,0,0)
A3: rate=0;type=0;fv=0;ppmt=6 | B3: =PPMT(0,6,12,1000,0,0)
A4: rate=0;type=0;fv=0;ppmt=12 | B4: =PPMT(0,12,12,1000,0,0)
A5: rate=0;type=0;fv=200;pmt | B5: =PMT(0,12,1000,200,0)
A6: rate=0;type=0;fv=200;ppmt=1 | B6: =PPMT(0,1,12,1000,200,0)
A7: rate=0;type=0;fv=200;ppmt=6 | B7: =PPMT(0,6,12,1000,200,0)
A8: rate=0;type=0;fv=200;ppmt=12 | B8: =PPMT(0,12,12,1000,200,0)
A9: rate=0;type=1;fv=0;pmt | B9: =PMT(0,12,1000,0,1)
A10: rate=0;type=1;fv=0;ppmt=1 | B10: =PPMT(0,1,12,1000,0,1)
A11: rate=0;type=1;fv=0;ppmt=6 | B11: =PPMT(0,6,12,1000,0,1)
A12: rate=0;type=1;fv=0;ppmt=12 | B12: =PPMT(0,12,12,1000,0,1)
A13: rate=0;type=1;fv=200;pmt | B13: =PMT(0,12,1000,200,1)
A14: rate=0;type=1;fv=200;ppmt=1 | B14: =PPMT(0,1,12,1000,200,1)
A15: rate=0;type=1;fv=200;ppmt=6 | B15: =PPMT(0,6,12,1000,200,1)
A16: rate=0;type=1;fv=200;ppmt=12 | B16: =PPMT(0,12,12,1000,200,1)
A17: rate=0.05;type=0;fv=0;pmt | B17: =PMT(0.05,12,1000,0,0)
A18: rate=0.05;type=0;fv=0;ppmt=1 | B18: =PPMT(0.05,1,12,1000,0,0)
A19: rate=0.05;type=0;fv=0;ppmt=6 | B19: =PPMT(0.05,6,12,1000,0,0)
A20: rate=0.05;type=0;fv=0;ppmt=12 | B20: =PPMT(0.05,12,12,1000,0,0)
A21: rate=0.05;type=0;fv=200;pmt | B21: =PMT(0.05,12,1000,200,0)
A22: rate=0.05;type=0;fv=200;ppmt=1 | B22: =PPMT(0.05,1,12,1000,200,0)
A23: rate=0.05;type=0;fv=200;ppmt=6 | B23: =PPMT(0.05,6,12,1000,200,0)
A24: rate=0.05;type=0;fv=200;ppmt=12 | B24: =PPMT(0.05,12,12,1000,200,0)
A25: rate=0.05;type=1;fv=0;pmt | B25: =PMT(0.05,12,1000,0,1)
A26: rate=0.05;type=1;fv=0;ppmt=1 | B26: =PPMT(0.05,1,12,1000,0,1)
A27: rate=0.05;type=1;fv=0;ppmt=6 | B27: =PPMT(0.05,6,12,1000,0,1)
A28: rate=0.05;type=1;fv=0;ppmt=12 | B28: =PPMT(0.05,12,12,1000,0,1)
A29: rate=0.05;type=1;fv=200;pmt | B29: =PMT(0.05,12,1000,200,1)
A30: rate=0.05;type=1;fv=200;ppmt=1 | B30: =PPMT(0.05,1,12,1000,200,1)
A31: rate=0.05;type=1;fv=200;ppmt=6 | B31: =PPMT(0.05,6,12,1000,200,1)
A32: rate=0.05;type=1;fv=200;ppmt=12 | B32: =PPMT(0.05,12,12,1000,200,1)
A33: rate=-0.02;type=0;fv=0;pmt | B33: =PMT(-0.02,12,1000,0,0)
A34: rate=-0.02;type=0;fv=0;ppmt=1 | B34: =PPMT(-0.02,1,12,1000,0,0)
A35: rate=-0.02;type=0;fv=0;ppmt=6 | B35: =PPMT(-0.02,6,12,1000,0,0)
A36: rate=-0.02;type=0;fv=0;ppmt=12 | B36: =PPMT(-0.02,12,12,1000,0,0)
A37: rate=-0.02;type=0;fv=200;pmt | B37: =PMT(-0.02,12,1000,200,0)
A38: rate=-0.02;type=0;fv=200;ppmt=1 | B38: =PPMT(-0.02,1,12,1000,200,0)
A39: rate=-0.02;type=0;fv=200;ppmt=6 | B39: =PPMT(-0.02,6,12,1000,200,0)
A40: rate=-0.02;type=0;fv=200;ppmt=12 | B40: =PPMT(-0.02,12,12,1000,200,0)
...

Sheet Input data
A1: 10 | B1: 20 | C1: 2
A2: 30 | B2: 40
A3: 123 | B3: TRUE
A5: =1/0 | B5: =12
